Workbook

Sheet 사용법
B2: 일일업무보고서 사용법
B4: <셀 색깔별 사용 법 >
C5: 기입X
C6: 수동기입
C7: 수식입력 되어 있으니 기입X
B9: <메뉴 별 사용 법>
B10: 호밀시리즈 (호라산, 호밀후르츠, 호밀비트)
B11: 생산량 X, 재고량X, 판매량O, 시식량O, 손실량O
B13: 슈톨렌, 파네토네, 미니파네토네(여름),구름빵
B14: 생산량 X, 재고량X, 판매량O, 시식량O, 손실량O
B15: (미니파네토네는 계절제품 상관없이 입력)
B17: 수프메뉴
B18: 생산량 X, 재고량X, 판매량O, 시식량O, 손실량O
B19: 손실량, 시식량 기준 : 수프 1잔 기준으로 절반 이하면 0.5 /절반 이상이면 1로 표기
B21: 선물 | C21: 금액을 지불하지 않고 영업시간 내에 제공된 완제품(협찬 포함)
B22: 쿠팡 | C22: 쿠팡잇츠 판매 내역
B23: 배민 | C23: 배달의민족 판매 내역
B24: 제로페이 | C24: 포스에 입력되지 않은 페이 결제 내역 (카카오, 서울페이 등), 계좌이체는 제외
B25: 택배 | C25: 택배 판매 내역
B26: 납품 | C26: 월말결제를 주로 하는 모든 납품 업체
B28: * 일일업무 보고서에 숫자로 기입하는 것은 완제품 기준 입니다.
B29: * 생산 공정상 발생하는 손실은 손실보고서 작성
B30: (손실보고서는 생산업무 전반에 발생하는 실수, 손해 모두 작성, 완제품으로 나오더라도 작성)
B31: * 일일업무보고서 내용 작성 누락 시 업무태도에 반영(제품의견, 서비스 내용은 출근직원은 반드시, 한줄이라도 작성할 것)

Sheet 1일
A1: 일 일 업 무 보 고 서
A2: 일 시 | C2: 2026년 2월 1일 (일요일) | E2: 확인 | F2: 작성자 | H2: 누계 매출액
A3: 지 점 명 | C3: 여의도 | D3: 점 | F3: 김윤희 | H3: =G11 -> 1418200
E5: 날씨 | F5: 외부온도 | G5: 내부온도 | H5: 외부습도 | I5: 내부습도
E6: 맑음 | F6: 1 | G6: 21 | H6: 0.3 | I6: 0.25
A9: 1. 금일 매출 실적 | B9: 실적 | C9: POS 매출 | E9: POS 외 매출 | G9: 총 매출 | I9: 객단가
C10: 매출액(원) | D10: 매출건수(건) | E10: 매출액(원) | F10: 매출건수(건) | G10: 총 매출액(원) | H10: 총 매출건수(건)
C11: 1307800 | D11: 87 | E11: =SUM(E55:I56) -> 110400 | F11: =SUM(E53:I54) -> 5 | G11: =C11+E11 -> 1418200 | H11: =D11+F11 -> 92 | I11: =G11/H11 -> 15415.217
A12: 2. 제품 판매량 | B12: 제품명 | C12: 생산량(ea) | D12: 손실량(ea) | E12: 시식량(ea) | F12: 기타(ea) In (+) / Out (-) | H12: 재고량(ea) | I12: 판매량(ea)
B13: 바게트 | C13: 21 | H13: 1 | I13: =C13-D13-D14*1/2-E13-E14*1/2+F13-H13-H14*1/2-I14*1/2 -> 19.5
B14: 바게트(H) | H14: 1
B15: 화바게트 | C15: 15 | H15: 9 | I15: =C15-D15-D16*1/2-E15-E16*1/2+F15-H15-H16*1/2-I16*1/2 -> 5.5
B16: 화바게트(H) | H16: 1
B17: 깜파뉴 | C17: 14 | I17: =C17-D17-D18*1/2-E17-E18*1/2+F17-H17-H18*1/2-I18*1/2 -> 14
B18: 깜파뉴(H)
B19: 식 빵 | C19: 10 | I19: =C19-D19-D20*1/2-E19-E20*1/2+F19-H19-H20*1/2-I20*1/2 -> 9.5
B20: 식 빵(H) | D20: 1
B21: 블랙올리브 | C21: 68 | D21: 1 | E21: 2 | H21: 20 | I21: =C21-D21-E21+F21-H21 -> 45
B22: 허 브 | C22: 14 | H22: 8 | I22: =C22-D22-E22+F22-H22 -> 6
B23: 치아바타 | C23: 86 | D23: 1 | E23: 3 | H23: 7 | I23: =C23-D23-D24-E23-E24+F23+F24-H23-H24-I24 -> #VALUE!
B24: 화치아바타 | E24: 1 | H24: `1
B25: 크로아상 | C25: 25 | H25: 6 | I25: =C25-D25-E25+F25-H25 -> 19
B26: 뺑오쇼콜라 | C26: 22 | I26: =C26-D26-E26+F26-H26 -> 22
B27: 플레인 스콘 | H27: 13 | I27: =C27-D27-E27+F27-H27 -> -13
B28: 크랜베리 스콘 | H28: 4 | I28: =C28-D28-E28+F28-H28 -> -4
B29: 브 레 첼 | C29: 40 | H29: 3 | I29: =C29-D29-E29+F29-H29 -> 37
B30: 스틱브레첼 | C30: 5 | E30: 2 | H30: 5 | I30: =C30-D30-D31-E30-E31+F30+F31-H30-H31-I31 -> -2
B31: 버터브레첼
B32: 호라산 통밀 | I32: 1
B33: 호밀비트
B34: 호밀후르츠 | I34: 1
B35: 구름빵 | I35: 15
B36: 무화과 호밀스틱 | C36: 15 | H36: 2 | I36: =C36-D36-E36+F36-H36 -> 13
B37: 봄날깜빠뉴 | I37: =C37-D37-D38*1/2-E37-E38*1/2+F37-H37-H38*1/2-I38*1/2 -> 0
B38: 봄날깜빠뉴(H)
B39: 여름메밀빵 | I39: =C39-D39-D40*1/2-E39-E40*1/2+F39-H39-H40*1/2-I40*1/2 -> 0
B40: 여름메밀빵(H)
B41: 가을애깜빠뉴 | I41: =C41-D41-D42*1/2-E41-E42*1/2+F41-H41-H42*1/2-I42*1/2 -> 0
B42: 가을애깜빠뉴(H)
B43: 슈톨렌
...

Sheet 2일
A1: 일 일 업 무 보 고 서
A2: 일 시 | C2: 2026년 2 월 2 일 ( 월요일) | E2: 확인 | F2: 작성자 | H2: 누계 매출액
A3: 지 점 명 | D3: 여의도점 | F3: 김도현 | H3: =G11+'1일'!H3:I3 -> 3475400
E5: 날씨 | F5: 외부온도 | G5: 내부온도 | H5: 외부습도 | I5: 내부습도
E6: 맑음 | F6: 0 | G6: 20.6 | H6: 0.39 | I6: 0.26
A9: 1. 금일 매출 실적 | B9: 실적 | C9: POS 매출 | E9: POS 외 매출 | G9: 총 매출 | I9: 객단가
C10: 매출액(원) | D10: 매출건수(건) | E10: 매출액(원) | F10: 매출건수(건) | G10: 총 매출액(원) | H10: 총 매출건수(건)
C11: 1826500 | D11: 139 | E11: =SUM(E55:I56) -> 230700 | F11: =SUM(E53:I54) -> 11 | G11: =C11+E11 -> 2057200 | H11: =D11+F11 -> 150 | I11: =G11/H11 -> 13714.667
A12: 2. 제품 판매량 | B12: 제품명 | C12: 생산량(ea) | D12: 손실량(ea) | E12: 시식량(ea) | F12: 기타(ea) In (+) / Out (-) | H12: 재고량(ea) | I12: 판매량(ea)
B13: 바게트 | C13: 17 | I13: =C13-D13-D14*1/2-E13-E14*1/2+F13-H13-H14*1/2-I14*1/2 -> 17
B14: 바게트(H)
B15: 화바게트 | C15: 14 | I15: =C15-D15-D16*1/2-E15-E16*1/2+F15-H15-H16*1/2-I16*1/2 -> 14
B16: 화바게트(H)
B17: 깜파뉴 | C17: 16 | H17: 2 | I17: =C17-D17-D18*1/2-E17-E18*1/2+F17-H17-H18*1/2-I18*1/2 -> 13.5
B18: 깜파뉴(H) | E18: 1
B19: 식 빵 | C19: 11 | D19: 1 | I19: =C19-D19-D20*1/2-E19-E20*1/2+F19-H19-H20*1/2-I20*1/2 -> 10
B20: 식 빵(H)
B21: 블랙올리브 | C21: 58 | E21: 1 | H21: 8 | I21: =C21-D21-E21+F21-H21 -> 49
B22: 허 브 | C22: 46 | E22: 1 | H22: 6 | I22: =C22-D22-E22+F22-H22 -> 39
B23: 치아바타 | C23: 109 | E23: 1 | I23: =C23-D23-D24-E23-E24+F23+F24-H23-H24-I24 -> 101
B24: 화치아바타 | E24: 1 | H24: 6
B25: 크로아상 | C25: 26 | D25: 2 | E25: 1 | H25: 4 | I25: =C25-D25-E25+F25-H25 -> 19
B26: 뺑오쇼콜라 | C26: 20 | I26: =C26-D26-E26+F26-H26 -> 20
B27: 플레인 스콘 | C27: 22 | H27: 3 | I27: =C27-D27-E27+F27-H27 -> 19
B28: 크랜베리 스콘 | C28: 28 | H28: 8 | I28: =C28-D28-E28+F28-H28 -> 20
B29: 브 레 첼 | C29: 5 | I29: =C29-D29-E29+F29-H29 -> 5
B30: 스틱브레첼 | C30: 79 | E30: 2 | H30: 3 | I30: =C30-D30-D31-E30-E31+F30+F31-H30-H31-I31 -> 74
B31: 버터브레첼
B32: 호라산 통밀 | I32: 2
B33: 호밀비트
B34: 호밀후르츠 | I34: 2
B35: 구름빵 | E35: 2 | I35: 16
B36: 무화과 호밀스틱 | C36: 15 | H36: 10 | I36: =C36-D36-E36+F36-H36 -> 5
B37: 봄날깜빠뉴 | I37: =C37-D37-D38*1/2-E37-E38*1/2+F37-H37-H38*1/2-I38*1/2 -> 0
B38: 봄날깜빠뉴(H)
B39: 여름메밀빵 | I39: =C39-D39-D40*1/2-E39-E40*1/2+F39-H39-H40*1/2-I40*1/2 -> 0
B40: 여름메밀빵(H)
B41: 가을애깜빠뉴 | I41: =C41-D41-D42*1/2-E41-E42*1/2+F41-H41-H42*1/2-I42*1/2 -> 0
B42: 가을애깜빠뉴(H)
B43: 슈톨렌
...

Sheet 3일
A1: 일 일 업 무 보 고 서
A2: 일 시 | C2: 2026 년 2월 3일 ( 화요일) | E2: 확인 | F2: 작성자 | H2: 누계 매출액
A3: 지 점 명 | C3: 여의도 | D3: 점 | F3: 정희주 | H3: =G11+'2일'!H3:I3 -> 5451100
E5: 날씨 | F5: 외부온도 | G5: 내부온도 | H5: 외부습도 | I5: 내부습도
E6: 맑음 | F6: 4 | G6: 23 | H6: 0.45 | I6: 0.25
A9: 1. 금일 매출 실적 | B9: 실적 | C9: POS 매출 | E9: POS 외 매출 | G9: 총 매출 | I9: 객단가
C10: 매출액(원) | D10: 매출건수(건) | E10: 매출액(원) | F10: 매출건수(건) | G10: 총 매출액(원) | H10: 총 매출건수(건)
C11: 1636100 | D11: 134 | E11: =SUM(E55:I56) -> 339600 | F11: =SUM(E53:I54) -> 12 | G11: =C11+E11 -> 1975700 | H11: =D11+F11 -> 146 | I11: =G11/H11 -> 13532.192
A12: 2. 제품 판매량 | B12: 제품명 | C12: 생산량(ea) | D12: 손실량(ea) | E12: 시식량(ea) | F12: 기타(ea) In (+) / Out (-) | H12: 재고량(ea) | I12: 판매량(ea)
B13: 바게트 | C13: 20 | H13: 3 | I13: =C13-D13-D14*1/2-E13-E14*1/2+F13-H13-H14*1/2-I14*1/2 -> 16.5
B14: 바게트(H) | H14: 1
B15: 화바게트 | C15: 17 | H15: 5 | I15: =C15-D15-D16*1/2-E15-E16*1/2+F15-H15-H16*1/2-I16*1/2 -> 11
B16: 화바게트(H) | E16: 1 | H16: 1
B17: 깜파뉴 | C17: 16 | H17: 7 | I17: =C17-D17-D18*1/2-E17-E18*1/2+F17-H17-H18*1/2-I18*1/2 -> 9
B18: 깜파뉴(H)
B19: 식 빵 | C19: 13 | H19: 3 | I19: =C19-D19-D20*1/2-E19-E20*1/2+F19-H19-H20*1/2-I20*1/2 -> 9.5
B20: 식 빵(H) | H20: 1
B21: 블랙올리브 | C21: 37 | E21: 1 | H21: 5 | I21: =C21-D21-E21+F21-H21 -> 31
B22: 허 브 | C22: 32 | H22: 12 | I22: =C22-D22-E22+F22-H22 -> 20
B23: 치아바타 | C23: 118 | E23: 2 | H23: 15 | I23: =C23-D23-D24-E23-E24+F23+F24-H23-H24-I24 -> 88
B24: 화치아바타 | D24: 1 | H24: 12
B25: 크로아상 | C25: 22 | D25: 1 | H25: 3 | I25: =C25-D25-E25+F25-H25 -> 18
B26: 뺑오쇼콜라 | C26: 44 | H26: 8 | I26: =C26-D26-E26+F26-H26 -> 36
B27: 플레인 스콘 | C27: 36 | H27: 16 | I27: =C27-D27-E27+F27-H27 -> 20
B28: 크랜베리 스콘 | C28: 29 | H28: 3 | I28: =C28-D28-E28+F28-H28 -> 26
B29: 브 레 첼 | C29: 5 | I29: =C29-D29-E29+F29-H29 -> 5
B30: 스틱브레첼 | C30: 78 | E30: 2 | H30: 16 | I30: =C30-D30-D31-E30-E31+F30+F31-H30-H31-I31 -> 60
B31: 버터브레첼
B32: 호라산 통밀
B33: 호밀비트
B34: 호밀후르츠 | I34: 1
B35: 구름빵 | I35: 20
B36: 무화과 호밀스틱 | C36: 20 | I36: =C36-D36-E36+F36-H36 -> 20
B37: 봄날깜빠뉴 | I37: =C37-D37-D38*1/2-E37-E38*1/2+F37-H37-H38*1/2-I38*1/2 -> 0
B38: 봄날깜빠뉴(H)
B39: 여름메밀빵 | I39: =C39-D39-D40*1/2-E39-E40*1/2+F39-H39-H40*1/2-I40*1/2 -> 0
B40: 여름메밀빵(H)
B41: 가을애깜빠뉴 | I41: =C41-D41-D42*1/2-E41-E42*1/2+F41-H41-H42*1/2-I42*1/2 -> 0
B42: 가을애깜빠뉴(H)
B43: 슈톨렌
...

Sheet 4일
A1: 일 일 업 무 보 고 서
A2: 일 시 | C2: 2026년 2월 4일 ( 화요일) | E2: 확인 | F2: 작성자 | H2: 누계 매출액
A3: 지 점 명 | C3: 여의도 | D3: 점 | F3: 유준모 | H3: =G11+'3일'!H3:I3 -> 7988100
E5: 날씨 | F5: 외부온도 | G5: 내부온도 | H5: 외부습도 | I5: 내부습도
E6: 구름 | F6: 6 | G6: 24 | H6: 0.25 | I6: 0.25
A9: 1. 금일 매출 실적 | B9: 실적 | C9: POS 매출 | E9: POS 외 매출 | G9: 총 매출 | I9: 객단가
C10: 매출액(원) | D10: 매출건수(건) | E10: 매출액(원) | F10: 매출건수(건) | G10: 총 매출액(원) | H10: 총 매출건수(건)
C11: 1955600 | D11: 146 | E11: =SUM(E55:I56) -> 581400 | F11: =SUM(E53:I54) -> 8 | G11: =C11+E11 -> 2537000 | H11: =D11+F11 -> 154 | I11: =G11/H11 -> 16474.026
A12: 2. 제품 판매량 | B12: 제품명 | C12: 생산량(ea) | D12: 손실량(ea) | E12: 시식량(ea) | F12: 기타(ea) In (+) / Out (-) | H12: 재고량(ea) | I12: 판매량(ea)
B13: 바게트 | C13: 43 | D13: 1 | I13: =C13-D13-D14*1/2-E13-E14*1/2+F13-H13-H14*1/2-I14*1/2 -> 41
B14: 바게트(H) | E14: 1 | H14: 1
B15: 화바게트 | C15: 17 | I15: =C15-D15-D16*1/2-E15-E16*1/2+F15-H15-H16*1/2-I16*1/2 -> 16.5
B16: 화바게트(H) | H16: 1
B17: 깜파뉴 | C17: 20 | I17: =C17-D17-D18*1/2-E17-E18*1/2+F17-H17-H18*1/2-I18*1/2 -> 19.5
B18: 깜파뉴(H) | E18: 1
B19: 식 빵 | C19: 13 | D19: 5 | I19: =C19-D19-D20*1/2-E19-E20*1/2+F19-H19-H20*1/2-I20*1/2 -> 8
B20: 식 빵(H)
B21: 블랙올리브 | C21: 90 | E21: 2 | H21: 1 | I21: =C21-D21-E21+F21-H21 -> 87
B22: 허 브 | C22: 35 | D22: 2 | E22: 1 | H22: 10 | I22: =C22-D22-E22+F22-H22 -> 22
B23: 치아바타 | C23: 122 | D23: 4 | E23: 3 | H23: 11 | I23: =C23-D23-D24-E23-E24+F23+F24-H23-H24-I24 -> 103
B24: 화치아바타 | E24: 1
B25: 크로아상 | C25: 25 | D25: 2 | I25: =C25-D25-E25+F25-H25 -> 23
B26: 뺑오쇼콜라 | C26: 22 | D26: 1 | I26: =C26-D26-E26+F26-H26 -> 21
B27: 플레인 스콘 | C27: 37 | E27: 2 | H27: 7 | I27: =C27-D27-E27+F27-H27 -> 28
B28: 크랜베리 스콘 | C28: 27 | D28: 2 | E28: 1 | I28: =C28-D28-E28+F28-H28 -> 24
B29: 브 레 첼 | C29: 5 | I29: =C29-D29-E29+F29-H29 -> 5
B30: 스틱브레첼 | C30: 61 | D30: 1 | I30: =C30-D30-D31-E30-E31+F30+F31-H30-H31-I31 -> 60
B31: 버터브레첼
B32: 호라산 통밀 | I32: 2
B33: 호밀비트 | I33: 4
B34: 호밀후르츠 | H34: 1 | I34: 1
B35: 구름빵 | E35: 3 | I35: 29
B36: 무화과 호밀스틱 | C36: 15 | I36: =C36-D36-E36+F36-H36 -> 15
B37: 봄날깜빠뉴 | I37: =C37-D37-D38*1/2-E37-E38*1/2+F37-H37-H38*1/2-I38*1/2 -> 0
B38: 봄날깜빠뉴(H)
B39: 여름메밀빵 | I39: =C39-D39-D40*1/2-E39-E40*1/2+F39-H39-H40*1/2-I40*1/2 -> 0
B40: 여름메밀빵(H)
B41: 가을애깜빠뉴 | I41: =C41-D41-D42*1/2-E41-E42*1/2+F41-H41-H42*1/2-I42*1/2 -> 0
B42: 가을애깜빠뉴(H)
B43: 슈톨렌
...

Sheet 5일
A1: 일 일 업 무 보 고 서
A2: 일 시 | C2: 2026년 2월 5일 ( 목요일) | E2: 확인 | F2: 작성자 | H2: 누계 매출액
A3: 지 점 명 | C3: 여의도 | D3: 점 | F3: 유준모 | H3: =G11+'4일'!H3:I3 -> 10153300
E5: 날씨 | F5: 외부온도 | G5: 내부온도 | H5: 외부습도 | I5: 내부습도
E6: 구름 | F6: 8 | G6: 24 | H6: 0.26 | I6: 0.25
A9: 1. 금일 매출 실적 | B9: 실적 | C9: POS 매출 | E9: POS 외 매출 | G9: 총 매출 | I9: 객단가
C10: 매출액(원) | D10: 매출건수(건) | E10: 매출액(원) | F10: 매출건수(건) | G10: 총 매출액(원) | H10: 총 매출건수(건)
C11: 1903400 | D11: 151 | E11: =SUM(E55:I56) -> 261800 | F11: =SUM(E53:I54) -> 8 | G11: =C11+E11 -> 2165200 | H11: =D11+F11 -> 159 | I11: =G11/H11 -> 13617.61
A12: 2. 제품 판매량 | B12: 제품명 | C12: 생산량(ea) | D12: 손실량(ea) | E12: 시식량(ea) | F12: 기타(ea) In (+) / Out (-) | H12: 재고량(ea) | I12: 판매량(ea)
B13: 바게트 | C13: 19 | D13: 1 | I13: =C13-D13-D14*1/2-E13-E14*1/2+F13-H13-H14*1/2-I14*1/2 -> 17.5
B14: 바게트(H) | E14: 1
B15: 화바게트 | C15: 11 | D15: 1 | I15: =C15-D15-D16*1/2-E15-E16*1/2+F15-H15-H16*1/2-I16*1/2 -> 9.5
B16: 화바게트(H) | E16: 1
B17: 깜파뉴 | C17: 18 | H17: 4 | I17: =C17-D17-D18*1/2-E17-E18*1/2+F17-H17-H18*1/2-I18*1/2 -> 11.5
B18: 깜파뉴(H) | E18: 5
B19: 식 빵 | C19: 12 | I19: =C19-D19-D20*1/2-E19-E20*1/2+F19-H19-H20*1/2-I20*1/2 -> 12
B20: 식 빵(H)
B21: 블랙올리브 | C21: 71 | H21: 11 | I21: =C21-D21-E21+F21-H21 -> 60
B22: 허 브 | C22: 35 | E22: 3 | H22: 5 | I22: =C22-D22-E22+F22-H22 -> 27
B23: 치아바타 | C23: 114 | D23: 3 | E23: 4 | H23: 12 | I23: =C23-D23-D24-E23-E24+F23+F24-H23-H24-I24 -> 94
B24: 화치아바타 | E24: 1
B25: 크로아상 | C25: 26 | D25: 2 | H25: 14 | I25: =C25-D25-E25+F25-H25 -> 10
B26: 뺑오쇼콜라 | C26: 21 | D26: 1 | I26: =C26-D26-E26+F26-H26 -> 20
B27: 플레인 스콘 | C27: 37 | E27: 2 | H27: 11 | I27: =C27-D27-E27+F27-H27 -> 24
B28: 크랜베리 스콘 | C28: 28 | E28: 3 | H28: 5 | I28: =C28-D28-E28+F28-H28 -> 20
B29: 브 레 첼 | C29: 5 | H29: 2 | I29: =C29-D29-E29+F29-H29 -> 3
B30: 스틱브레첼 | C30: 76 | H30: 4 | I30: =C30-D30-D31-E30-E31+F30+F31-H30-H31-I31 -> 72
B31: 버터브레첼
B32: 호라산 통밀 | I32: 2
B33: 호밀비트 | H33: 1 | I33: 1
B34: 호밀후르츠 | I34: 2
B35: 구름빵 | I35: 23
B36: 무화과 호밀스틱 | C36: 10 | I36: =C36-D36-E36+F36-H36 -> 10
B37: 봄날깜빠뉴 | I37: =C37-D37-D38*1/2-E37-E38*1/2+F37-H37-H38*1/2-I38*1/2 -> 0
B38: 봄날깜빠뉴(H)
B39: 여름메밀빵 | I39: =C39-D39-D40*1/2-E39-E40*1/2+F39-H39-H40*1/2-I40*1/2 -> 0
B40: 여름메밀빵(H)
B41: 가을애깜빠뉴 | I41: =C41-D41-D42*1/2-E41-E42*1/2+F41-H41-H42*1/2-I42*1/2 -> 0
B42: 가을애깜빠뉴(H)
B43: 슈톨렌
...

Sheet 6일
A1: 일 일 업 무 보 고 서
A2: 일 시 | C2: 2026년 2월 6일 ( 금요일) | E2: 확인 | F2: 작성자 | H2: 누계 매출액
A3: 지 점 명 | C3: 여의도 | D3: 점 | F3: 유준모 | H3: =G11+'5일'!H3:I3 -> 12336700
E5: 날씨 | F5: 외부온도 | G5: 내부온도 | H5: 외부습도 | I5: 내부습도
F6: -4 | G6: 24 | H6: 0.24 | I6: 0.25
A9: 1. 금일 매출 실적 | B9: 실적 | C9: POS 매출 | E9: POS 외 매출 | G9: 총 매출 | I9: 객단가
C10: 매출액(원) | D10: 매출건수(건) | E10: 매출액(원) | F10: 매출건수(건) | G10: 총 매출액(원) | H10: 총 매출건수(건)
C11: 2004700 | D11: 156 | E11: =SUM(E55:I56) -> 178700 | F11: =SUM(E53:I54) -> 11 | G11: =C11+E11 -> 2183400 | H11: =D11+F11 -> 167 | I11: =G11/H11 -> 13074.251
A12: 2. 제품 판매량 | B12: 제품명 | C12: 생산량(ea) | D12: 손실량(ea) | E12: 시식량(ea) | F12: 기타(ea) In (+) / Out (-) | H12: 재고량(ea) | I12: 판매량(ea)
B13: 바게트 | C13: 30 | I13: =C13-D13-D14*1/2-E13-E14*1/2+F13-H13-H14*1/2-I14*1/2 -> 30
B14: 바게트(H)
B15: 화바게트 | C15: 22 | I15: =C15-D15-D16*1/2-E15-E16*1/2+F15-H15-H16*1/2-I16*1/2 -> 21.5
B16: 화바게트(H) | E16: 1
B17: 깜파뉴 | C17: 36 | I17: =C17-D17-D18*1/2-E17-E18*1/2+F17-H17-H18*1/2-I18*1/2 -> 36
B18: 깜파뉴(H)
B19: 식 빵 | C19: 17 | I19: =C19-D19-D20*1/2-E19-E20*1/2+F19-H19-H20*1/2-I20*1/2 -> 17
B20: 식 빵(H)
B21: 블랙올리브 | C21: 95 | H21: 5 | I21: =C21-D21-E21+F21-H21 -> 90
B22: 허 브 | C22: 57 | E22: 3 | H22: 19 | I22: =C22-D22-E22+F22-H22 -> 35
B23: 치아바타 | C23: 172 | E23: 1 | H23: 12 | I23: =C23-D23-D24-E23-E24+F23+F24-H23-H24-I24 -> 153
B24: 화치아바타 | D24: 4 | H24: 2
B25: 크로아상 | C25: 48 | D25: 3 | I25: =C25-D25-E25+F25-H25 -> 45
B26: 뺑오쇼콜라 | C26: 44 | I26: =C26-D26-E26+F26-H26 -> 44
B27: 플레인 스콘 | C27: 34 | I27: =C27-D27-E27+F27-H27 -> 34
B28: 크랜베리 스콘 | C28: 31 | I28: =C28-D28-E28+F28-H28 -> 31
B29: 브 레 첼 | C29: 10 | I29: =C29-D29-E29+F29-H29 -> 10
B30: 스틱브레첼 | C30: 107 | D30: 4 | E30: 1 | H30: 4 | I30: =C30-D30-D31-E30-E31+F30+F31-H30-H31-I31 -> 98
B31: 버터브레첼
B32: 호라산 통밀 | I32: 1
B33: 호밀비트 | I33: 2
B34: 호밀후르츠 | I34: 2
B35: 구름빵 | I35: 32
B36: 무화과 호밀스틱 | C36: 20 | D36: 1 | I36: =C36-D36-E36+F36-H36 -> 19
B37: 봄날깜빠뉴 | I37: =C37-D37-D38*1/2-E37-E38*1/2+F37-H37-H38*1/2-I38*1/2 -> 0
B38: 봄날깜빠뉴(H)
B39: 여름메밀빵 | I39: =C39-D39-D40*1/2-E39-E40*1/2+F39-H39-H40*1/2-I40*1/2 -> 0
B40: 여름메밀빵(H)
B41: 가을애깜빠뉴 | I41: =C41-D41-D42*1/2-E41-E42*1/2+F41-H41-H42*1/2-I42*1/2 -> 0
B42: 가을애깜빠뉴(H)
B43: 슈톨렌
...

Sheet 7일
A1: 일 일 업 무 보 고 서
A2: 일 시 | C2: 2026년 2월 7 일 ( 토요일) | E2: 확인 | F2: 작성자 | H2: 누계 매출액
A3: 지 점 명 | C3: 여의도 | D3: 점 | F3: 김도현 | H3: =G11+'6일'!H3:I3 -> 14617500
E5: 날씨 | F5: 외부온도 | G5: 내부온도 | H5: 외부습도 | I5: 내부습도
E6: 맑음 | F6: -5 | G6: 20 | H6: 0.26 | I6: 0.32
A9: 1. 금일 매출 실적 | B9: 실적 | C9: POS 매출 | E9: POS 외 매출 | G9: 총 매출 | I9: 객단가
C10: 매출액(원) | D10: 매출건수(건) | E10: 매출액(원) | F10: 매출건수(건) | G10: 총 매출액(원) | H10: 총 매출건수(건)
C11: 1972600 | D11: 143 | E11: =SUM(E55:I56) -> 308200 | F11: =SUM(E53:I54) -> 12 | G11: =C11+E11 -> 2280800 | H11: =D11+F11 -> 155 | I11: =G11/H11 -> 14714.839
A12: 2. 제품 판매량 | B12: 제품명 | C12: 생산량(ea) | D12: 손실량(ea) | E12: 시식량(ea) | F12: 기타(ea) In (+) / Out (-) | H12: 재고량(ea) | I12: 판매량(ea)
B13: 바게트 | C13: 44 | I13: =C13-D13-D14*1/2-E13-E14*1/2+F13-H13-H14*1/2-I14*1/2 -> 44
B14: 바게트(H)
B15: 화바게트 | C15: 23 | I15: =C15-D15-D16*1/2-E15-E16*1/2+F15-H15-H16*1/2-I16*1/2 -> 23
B16: 화바게트(H)
B17: 깜파뉴 | C17: 36 | I17: =C17-D17-D18*1/2-E17-E18*1/2+F17-H17-H18*1/2-I18*1/2 -> 36
B18: 깜파뉴(H)
B19: 식 빵 | C19: 17 | D19: 1 | I19: =C19-D19-D20*1/2-E19-E20*1/2+F19-H19-H20*1/2-I20*1/2 -> 16
B20: 식 빵(H)
B21: 블랙올리브 | C21: 94 | E21: 1 | I21: =C21-D21-E21+F21-H21 -> 93
B22: 허 브 | C22: 57 | E22: 2 | H22: 10 | I22: =C22-D22-E22+F22-H22 -> 45
B23: 치아바타 | C23: 180 | D23: 11 | E23: 4 | H23: 15 | I23: =C23-D23-D24-E23-E24+F23+F24-H23-H24-I24 -> 127
B24: 화치아바타 | D24: 3 | E24: 1 | H24: 19
B25: 크로아상 | C25: 48 | D25: 5 | H25: 7 | I25: =C25-D25-E25+F25-H25 -> 36
B26: 뺑오쇼콜라 | C26: 44 | I26: =C26-D26-E26+F26-H26 -> 44
B27: 플레인 스콘 | C27: 26 | E27: 1 | I27: =C27-D27-E27+F27-H27 -> 25
B28: 크랜베리 스콘 | C28: 35 | E28: 3 | I28: =C28-D28-E28+F28-H28 -> 32
B29: 브 레 첼 | C29: 10 | I29: =C29-D29-E29+F29-H29 -> 10
B30: 스틱브레첼 | C30: 147 | H30: 7 | I30: =C30-D30-D31-E30-E31+F30+F31-H30-H31-I31 -> 138
B31: 버터브레첼 | E31: 2
B32: 호라산 통밀 | I32: 2
B33: 호밀비트 | I33: 2
B34: 호밀후르츠 | I34: 2
B35: 구름빵 | I35: 16
B36: 무화과 호밀스틱 | C36: 20 | I36: =C36-D36-E36+F36-H36 -> 20
B37: 봄날깜빠뉴 | I37: =C37-D37-D38*1/2-E37-E38*1/2+F37-H37-H38*1/2-I38*1/2 -> 0
B38: 봄날깜빠뉴(H)
B39: 여름메밀빵 | I39: =C39-D39-D40*1/2-E39-E40*1/2+F39-H39-H40*1/2-I40*1/2 -> 0
B40: 여름메밀빵(H)
B41: 가을애깜빠뉴 | I41: =C41-D41-D42*1/2-E41-E42*1/2+F41-H41-H42*1/2-I42*1/2 -> 0
B42: 가을애깜빠뉴(H)
B43: 슈톨렌
...

Sheet 8일
A1: 일 일 업 무 보 고 서
A2: 일 시 | C2: 2026 년 2 월 8 일 ( 일요일) | E2: 확인 | F2: 작성자 | H2: 누계 매출액
A3: 지 점 명 | D3: 점 | F3: 김도현 | H3: =G11+'7일'!H3:I3 -> 16018600
E5: 날씨 | F5: 외부온도 | G5: 내부온도 | H5: 외부습도 | I5: 내부습도
E6: 맑음 | F6: -4 | H6: 0.25
A9: 1. 금일 매출 실적 | B9: 실적 | C9: POS 매출 | E9: POS 외 매출 | G9: 총 매출 | I9: 객단가
C10: 매출액(원) | D10: 매출건수(건) | E10: 매출액(원) | F10: 매출건수(건) | G10: 총 매출액(원) | H10: 총 매출건수(건)
C11: 1188100 | D11: 76 | E11: =SUM(E55:I56) -> 213000 | F11: =SUM(E53:I54) -> 10 | G11: =C11+E11 -> 1401100 | H11: =D11+F11 -> 86 | I11: =G11/H11 -> 16291.86
A12: 2. 제품 판매량 | B12: 제품명 | C12: 생산량(ea) | D12: 손실량(ea) | E12: 시식량(ea) | F12: 기타(ea) In (+) / Out (-) | H12: 재고량(ea) | I12: 판매량(ea)
B13: 바게트 | C13: 16 | I13: =C13-D13-D14*1/2-E13-E14*1/2+F13-H13-H14*1/2-I14*1/2 -> 15.5
B14: 바게트(H) | H14: 1
B15: 화바게트 | C15: 40 | H15: 3 | I15: =C15-D15-D16*1/2-E15-E16*1/2+F15-H15-H16*1/2-I16*1/2 -> 36.5
B16: 화바게트(H) | H16: 1
B17: 깜파뉴 | C17: 36 | H17: 2 | I17: =C17-D17-D18*1/2-E17-E18*1/2+F17-H17-H18*1/2-I18*1/2 -> 34
B18: 깜파뉴(H)
B19: 식 빵 | C19: 17 | I19: =C19-D19-D20*1/2-E19-E20*1/2+F19-H19-H20*1/2-I20*1/2 -> 17
B20: 식 빵(H)
B21: 블랙올리브 | C21: 84 | H21: 11 | I21: =C21-D21-E21+F21-H21 -> 73
B22: 허 브 | C22: 50 | H22: 3 | I22: =C22-D22-E22+F22-H22 -> 47
B23: 치아바타 | C23: 161 | H23: 19 | I23: =C23-D23-D24-E23-E24+F23+F24-H23-H24-I24 -> 132
B24: 화치아바타 | D24: 3 | E24: 1 | H24: 6
B25: 크로아상 | C25: 48 | D25: 3 | H25: 20 | I25: =C25-D25-E25+F25-H25 -> 25
B26: 뺑오쇼콜라 | C26: 44 | H26: 5 | I26: =C26-D26-E26+F26-H26 -> 39
B27: 플레인 스콘 | C27: 25 | I27: =C27-D27-E27+F27-H27 -> 25
B28: 크랜베리 스콘 | C28: 37 | H28: 9 | I28: =C28-D28-E28+F28-H28 -> 28
B29: 브 레 첼 | C29: 10 | I29: =C29-D29-E29+F29-H29 -> 10
B30: 스틱브레첼 | C30: 111 | D30: 3 | E30: 3 | H30: 9 | I30: =C30-D30-D31-E30-E31+F30+F31-H30-H31-I31 -> 96
B31: 버터브레첼
B32: 호라산 통밀
B33: 호밀비트 | I33: 1
B34: 호밀후르츠
B35: 구름빵 | I35: 6
B36: 무화과 호밀스틱 | C36: 20 | H36: 5 | I36: =C36-D36-E36+F36-H36 -> 15
B37: 봄날깜빠뉴 | I37: =C37-D37-D38*1/2-E37-E38*1/2+F37-H37-H38*1/2-I38*1/2 -> 0
B38: 봄날깜빠뉴(H)
B39: 여름메밀빵 | I39: =C39-D39-D40*1/2-E39-E40*1/2+F39-H39-H40*1/2-I40*1/2 -> 0
B40: 여름메밀빵(H)
B41: 가을애깜빠뉴 | I41: =C41-D41-D42*1/2-E41-E42*1/2+F41-H41-H42*1/2-I42*1/2 -> 0
B42: 가을애깜빠뉴(H)
B43: 슈톨렌
...

Sheet 9일
A1: 일 일 업 무 보 고 서
A2: 일 시 | C2: 2026년 2월 10일 ( 월요일) | E2: 확인 | F2: 작성자 | H2: 누계 매출액
A3: 지 점 명 | C3: 여의도 | D3: 점 | F3: 유준모 | H3: =G11+'8일'!H3:I3 -> 17614900
E5: 날씨 | F5: 외부온도 | G5: 내부온도 | H5: 외부습도 | I5: 내부습도
E6: 맑음 | F6: 2 | G6: 24 | H6: 0.25 | I6: 0.25
A9: 1. 금일 매출 실적 | B9: 실적 | C9: POS 매출 | E9: POS 외 매출 | G9: 총 매출 | I9: 객단가
C10: 매출액(원) | D10: 매출건수(건) | E10: 매출액(원) | F10: 매출건수(건) | G10: 총 매출액(원) | H10: 총 매출건수(건)
C11: 1392500 | D11: 112 | E11: =SUM(E55:I56) -> 203800 | F11: =SUM(E53:I54) -> 10 | G11: =C11+E11 -> 1596300 | H11: =D11+F11 -> 122 | I11: =G11/H11 -> 13084.426
A12: 2. 제품 판매량 | B12: 제품명 | C12: 생산량(ea) | D12: 손실량(ea) | E12: 시식량(ea) | F12: 기타(ea) In (+) / Out (-) | H12: 재고량(ea) | I12: 판매량(ea)
B13: 바게트 | C13: 30 | I13: =C13-D13-D14*1/2-E13-E14*1/2+F13-H13-H14*1/2-I14*1/2 -> 30
B14: 바게트(H)
B15: 화바게트 | C15: 28 | I15: =C15-D15-D16*1/2-E15-E16*1/2+F15-H15-H16*1/2-I16*1/2 -> 28
B16: 화바게트(H)
B17: 깜파뉴 | C17: 29 | I17: =C17-D17-D18*1/2-E17-E18*1/2+F17-H17-H18*1/2-I18*1/2 -> 29
B18: 깜파뉴(H)
B19: 식 빵 | C19: 16 | I19: =C19-D19-D20*1/2-E19-E20*1/2+F19-H19-H20*1/2-I20*1/2 -> 16
B20: 식 빵(H)
B21: 블랙올리브 | C21: 82 | I21: =C21-D21-E21+F21-H21 -> 82
B22: 허 브 | C22: 44 | E22: 1 | I22: =C22-D22-E22+F22-H22 -> 43
B23: 치아바타 | C23: 185 | D23: 1 | I23: =C23-D23-D24-E23-E24+F23+F24-H23-H24-I24 -> 184
B24: 화치아바타
B25: 크로아상 | C25: 48 | I25: =C25-D25-E25+F25-H25 -> 48
B26: 뺑오쇼콜라 | C26: 44 | I26: =C26-D26-E26+F26-H26 -> 44
B27: 플레인 스콘 | C27: 35 | I27: =C27-D27-E27+F27-H27 -> 35
B28: 크랜베리 스콘 | C28: 30 | I28: =C28-D28-E28+F28-H28 -> 30
B29: 브 레 첼 | C29: 10 | I29: =C29-D29-E29+F29-H29 -> 10
B30: 스틱브레첼 | C30: 111 | E30: 1 | I30: =C30-D30-D31-E30-E31+F30+F31-H30-H31-I31 -> 110
B31: 버터브레첼
B32: 호라산 통밀 | I32: 1
B33: 호밀비트
B34: 호밀후르츠
B35: 구름빵 | I35: 0
B36: 무화과 호밀스틱 | C36: 20 | I36: =C36-D36-E36+F36-H36 -> 20
B37: 봄날깜빠뉴 | I37: =C37-D37-D38*1/2-E37-E38*1/2+F37-H37-H38*1/2-I38*1/2 -> 0
B38: 봄날깜빠뉴(H)
B39: 여름메밀빵 | I39: =C39-D39-D40*1/2-E39-E40*1/2+F39-H39-H40*1/2-I40*1/2 -> 0
B40: 여름메밀빵(H)
B41: 가을애깜빠뉴 | I41: =C41-D41-D42*1/2-E41-E42*1/2+F41-H41-H42*1/2-I42*1/2 -> 0
B42: 가을애깜빠뉴(H)
B43: 슈톨렌
...

Sheet 10일
A1: 일 일 업 무 보 고 서
A2: 일 시 | C2: 2026년 2월 10일 ( 화요일) | E2: 확인 | F2: 작성자 | H2: 누계 매출액
A3: 지 점 명 | C3: 여의도 | D3: 점 | F3: 유준모 | H3: =G11+'9일'!H3:I3 -> 19782800
E5: 날씨 | F5: 외부온도 | G5: 내부온도 | H5: 외부습도 | I5: 내부습도
E6: 구름 | F6: 4 | G6: 23 | H6: 0.78 | I6: 0.27
A9: 1. 금일 매출 실적 | B9: 실적 | C9: POS 매출 | E9: POS 외 매출 | G9: 총 매출 | I9: 객단가
C10: 매출액(원) | D10: 매출건수(건) | E10: 매출액(원) | F10: 매출건수(건) | G10: 총 매출액(원) | H10: 총 매출건수(건)
C11: 1621800 | D11: 143 | E11: =SUM(E55:I56) -> 546100 | F11: =SUM(E53:I54) -> 6 | G11: =C11+E11 -> 2167900 | H11: =D11+F11 -> 149 | I11: =G11/H11 -> 14549.664
A12: 2. 제품 판매량 | B12: 제품명 | C12: 생산량(ea) | D12: 손실량(ea) | E12: 시식량(ea) | F12: 기타(ea) In (+) / Out (-) | H12: 재고량(ea) | I12: 판매량(ea)
B13: 바게트 | C13: 28 | H13: 9 | I13: =C13-D13-D14*1/2-E13-E14*1/2+F13-H13-H14*1/2-I14*1/2 -> 18
B14: 바게트(H) | D14: 1 | H14: 1
B15: 화바게트 | C15: 15 | H15: 1 | I15: =C15-D15-D16*1/2-E15-E16*1/2+F15-H15-H16*1/2-I16*1/2 -> 14
B16: 화바게트(H)
B17: 깜파뉴 | C17: 16 | D17: 1 | H17: 1 | I17: =C17-D17-D18*1/2-E17-E18*1/2+F17-H17-H18*1/2-I18*1/2 -> 12.5
B18: 깜파뉴(H) | E18: 3
B19: 식 빵 | C19: 11 | I19: =C19-D19-D20*1/2-E19-E20*1/2+F19-H19-H20*1/2-I20*1/2 -> 11
B20: 식 빵(H)
B21: 블랙올리브 | C21: 52 | E21: 2 | I21: =C21-D21-E21+F21-H21 -> 50
B22: 허 브 | C22: 30 | E22: 1 | H22: 9 | I22: =C22-D22-E22+F22-H22 -> 20
B23: 치아바타 | C23: 117 | E23: 8 | H23: 28 | I23: =C23-D23-D24-E23-E24+F23+F24-H23-H24-I24 -> 81
B24: 화치아바타
B25: 크로아상 | C25: 21 | D25: 1 | I25: =C25-D25-E25+F25-H25 -> 20
B26: 뺑오쇼콜라 | C26: 22 | I26: =C26-D26-E26+F26-H26 -> 22
B27: 플레인 스콘 | C27: 23 | I27: =C27-D27-E27+F27-H27 -> 23
B28: 크랜베리 스콘 | C28: 30 | D28: 2 | I28: =C28-D28-E28+F28-H28 -> 28
B29: 브 레 첼 | C29: 5 | D29: 3 | I29: =C29-D29-E29+F29-H29 -> 2
B30: 스틱브레첼 | C30: 43 | D30: 14 | I30: =C30-D30-D31-E30-E31+F30+F31-H30-H31-I31 -> 29
B31: 버터브레첼
B32: 호라산 통밀 | I32: 2
B33: 호밀비트 | I33: 2
B34: 호밀후르츠
B35: 구름빵
B36: 무화과 호밀스틱 | C36: 15 | E36: 1 | I36: =C36-D36-E36+F36-H36 -> 14
B37: 봄날깜빠뉴 | I37: =C37-D37-D38*1/2-E37-E38*1/2+F37-H37-H38*1/2-I38*1/2 -> 0
B38: 봄날깜빠뉴(H)
B39: 여름메밀빵 | I39: =C39-D39-D40*1/2-E39-E40*1/2+F39-H39-H40*1/2-I40*1/2 -> 0
B40: 여름메밀빵(H)
B41: 가을애깜빠뉴 | I41: =C41-D41-D42*1/2-E41-E42*1/2+F41-H41-H42*1/2-I42*1/2 -> 0
B42: 가을애깜빠뉴(H)
B43: 슈톨렌
...

Sheet 11일
A1: 일 일 업 무 보 고 서
A2: 일 시 | C2: 2026 년 2월 11일 ( 수요일) | E2: 확인 | F2: 작성자 | H2: 누계 매출액
A3: 지 점 명 | C3: 여의도 | D3: 점 | F3: 유준모 | H3: =G11+'10일'!H3:I3 -> 21992400
E5: 날씨 | F5: 외부온도 | G5: 내부온도 | H5: 외부습도 | I5: 내부습도
F6: 6 | G6: 23 | H6: 0.55 | I6: 0.23
A9: 1. 금일 매출 실적 | B9: 실적 | C9: POS 매출 | E9: POS 외 매출 | G9: 총 매출 | I9: 객단가
C10: 매출액(원) | D10: 매출건수(건) | E10: 매출액(원) | F10: 매출건수(건) | G10: 총 매출액(원) | H10: 총 매출건수(건)
C11: 1739600 | D11: 131 | E11: =SUM(E55:I56) -> 470000 | F11: =SUM(E53:I54) -> 15 | G11: =C11+E11 -> 2209600 | H11: =D11+F11 -> 146 | I11: =G11/H11 -> 15134.247
A12: 2. 제품 판매량 | B12: 제품명 | C12: 생산량(ea) | D12: 손실량(ea) | E12: 시식량(ea) | F12: 기타(ea) In (+) / Out (-) | H12: 재고량(ea) | I12: 판매량(ea)
B13: 바게트 | C13: 40 | I13: =C13-D13-D14*1/2-E13-E14*1/2+F13-H13-H14*1/2-I14*1/2 -> 40
B14: 바게트(H)
B15: 화바게트 | C15: 32 | I15: =C15-D15-D16*1/2-E15-E16*1/2+F15-H15-H16*1/2-I16*1/2 -> 32
B16: 화바게트(H)
B17: 깜파뉴 | C17: 42 | I17: =C17-D17-D18*1/2-E17-E18*1/2+F17-H17-H18*1/2-I18*1/2 -> 40.5
B18: 깜파뉴(H) | E18: 3
B19: 식 빵 | C19: 15 | I19: =C19-D19-D20*1/2-E19-E20*1/2+F19-H19-H20*1/2-I20*1/2 -> 15
B20: 식 빵(H)
B21: 블랙올리브 | C21: 93 | E21: 2 | I21: =C21-D21-E21+F21-H21 -> 91
B22: 허 브 | C22: 50 | E22: 3 | I22: =C22-D22-E22+F22-H22 -> 47
B23: 치아바타 | C23: 172 | D23: 4 | E23: 2 | I23: =C23-D23-D24-E23-E24+F23+F24-H23-H24-I24 -> 162
B24: 화치아바타 | D24: 3 | E24: 1
B25: 크로아상 | C25: 48 | D25: 1 | I25: =C25-D25-E25+F25-H25 -> 47
B26: 뺑오쇼콜라 | C26: 44 | I26: =C26-D26-E26+F26-H26 -> 44
B27: 플레인 스콘 | C27: 34 | E27: 1 | I27: =C27-D27-E27+F27-H27 -> 33
B28: 크랜베리 스콘 | C28: 30 | E28: 1 | I28: =C28-D28-E28+F28-H28 -> 29
B29: 브 레 첼 | C29: 10 | H29: 1 | I29: =C29-D29-E29+F29-H29 -> 9
B30: 스틱브레첼 | C30: 105 | I30: =C30-D30-D31-E30-E31+F30+F31-H30-H31-I31 -> 105
B31: 버터브레첼
B32: 호라산 통밀 | I32: 2
B33: 호밀비트 | I33: 2
B34: 호밀후르츠
B35: 구름빵 | I35: 18
B36: 무화과 호밀스틱 | C36: 20 | I36: =C36-D36-E36+F36-H36 -> 20
B37: 봄날깜빠뉴 | I37: =C37-D37-D38*1/2-E37-E38*1/2+F37-H37-H38*1/2-I38*1/2 -> 0
B38: 봄날깜빠뉴(H)
B39: 여름메밀빵 | I39: =C39-D39-D40*1/2-E39-E40*1/2+F39-H39-H40*1/2-I40*1/2 -> 0
B40: 여름메밀빵(H)
B41: 가을애깜빠뉴 | I41: =C41-D41-D42*1/2-E41-E42*1/2+F41-H41-H42*1/2-I42*1/2 -> 0
B42: 가을애깜빠뉴(H)
B43: 슈톨렌
...

Sheet 12일
A1: 일 일 업 무 보 고 서
A2: 일 시 | C2: 2026 년 2월 12일 ( 목요일) | E2: 확인 | F2: 작성자 | H2: 누계 매출액
A3: 지 점 명 | C3: 여의도 | D3: 점 | F3: 정희주 | H3: =G11+'11일'!H3:I3 -> 24273400
E5: 날씨 | F5: 외부온도 | G5: 내부온도 | H5: 외부습도 | I5: 내부습도
E6: 흐림 | F6: 8 | G6: 22 | H6: 0.5 | I6: 0.26
A9: 1. 금일 매출 실적 | B9: 실적 | C9: POS 매출 | E9: POS 외 매출 | G9: 총 매출 | I9: 객단가
C10: 매출액(원) | D10: 매출건수(건) | E10: 매출액(원) | F10: 매출건수(건) | G10: 총 매출액(원) | H10: 총 매출건수(건)
C11: 1995300 | D11: 149 | E11: =SUM(E55:I56) -> 285700 | F11: =SUM(E53:I54) -> 10 | G11: =C11+E11 -> 2281000 | H11: =D11+F11 -> 159 | I11: =G11/H11 -> 14345.912
A12: 2. 제품 판매량 | B12: 제품명 | C12: 생산량(ea) | D12: 손실량(ea) | E12: 시식량(ea) | F12: 기타(ea) In (+) / Out (-) | H12: 재고량(ea) | I12: 판매량(ea)
B13: 바게트 | C13: 35 | H13: 3 | I13: =C13-D13-D14*1/2-E13-E14*1/2+F13-H13-H14*1/2-I14*1/2 -> 31.5
B14: 바게트(H) | H14: 1
B15: 화바게트 | C15: 37 | D15: 1 | H15: 2 | I15: =C15-D15-D16*1/2-E15-E16*1/2+F15-H15-H16*1/2-I16*1/2 -> 33.5
B16: 화바게트(H) | H16: 1
B17: 깜파뉴 | C17: 42 | I17: =C17-D17-D18*1/2-E17-E18*1/2+F17-H17-H18*1/2-I18*1/2 -> 41.5
B18: 깜파뉴(H) | E18: 1
B19: 식 빵 | C19: 16 | H19: 1 | I19: =C19-D19-D20*1/2-E19-E20*1/2+F19-H19-H20*1/2-I20*1/2 -> 15
B20: 식 빵(H)
B21: 블랙올리브 | C21: 91 | D21: 1 | H21: 4 | I21: =C21-D21-E21+F21-H21 -> 86
B22: 허 브 | C22: 50 | D22: 2 | E22: 1 | I22: =C22-D22-E22+F22-H22 -> 47
B23: 치아바타 | C23: 170 | D23: 2 | I23: =C23-D23-D24-E23-E24+F23+F24-H23-H24-I24 -> 166
B24: 화치아바타 | D24: 1 | E24: 1
B25: 크로아상 | C25: 48 | D25: 2 | I25: =C25-D25-E25+F25-H25 -> 46
B26: 뺑오쇼콜라 | C26: 44 | D26: 3 | I26: =C26-D26-E26+F26-H26 -> 41
B27: 플레인 스콘 | C27: 34 | I27: =C27-D27-E27+F27-H27 -> 34
B28: 크랜베리 스콘 | C28: 30 | I28: =C28-D28-E28+F28-H28 -> 30
B29: 브 레 첼 | C29: 10 | I29: =C29-D29-E29+F29-H29 -> 10
B30: 스틱브레첼 | C30: 107 | D30: 4 | I30: =C30-D30-D31-E30-E31+F30+F31-H30-H31-I31 -> 103
B31: 버터브레첼
B32: 호라산 통밀
B33: 호밀비트 | I33: 2
B34: 호밀후르츠
B35: 구름빵 | E35: 1 | I35: 25
B36: 무화과 호밀스틱 | C36: 20 | I36: =C36-D36-E36+F36-H36 -> 20
B37: 봄날깜빠뉴 | I37: =C37-D37-D38*1/2-E37-E38*1/2+F37-H37-H38*1/2-I38*1/2 -> 0
B38: 봄날깜빠뉴(H)
B39: 여름메밀빵 | I39: =C39-D39-D40*1/2-E39-E40*1/2+F39-H39-H40*1/2-I40*1/2 -> 0
B40: 여름메밀빵(H)
B41: 가을애깜빠뉴 | I41: =C41-D41-D42*1/2-E41-E42*1/2+F41-H41-H42*1/2-I42*1/2 -> 0
B42: 가을애깜빠뉴(H)
B43: 슈톨렌
...

Sheet 13일
A1: 일 일 업 무 보 고 서
A2: 일 시 | C2: 2026년 2월 13일 (금요일) | E2: 확인 | F2: 작성자 | H2: 누계 매출액
A3: 지 점 명 | C3: 여의도 | D3: 점 | F3: 김윤희 | H3: =G11+'12일'!H3:I3 -> 26716500
E5: 날씨 | F5: 외부온도 | G5: 내부온도 | H5: 외부습도 | I5: 내부습도
E6: 흐림 | F6: 7 | G6: 24 | H6: 0.74 | I6: 0.26
A9: 1. 금일 매출 실적 | B9: 실적 | C9: POS 매출 | E9: POS 외 매출 | G9: 총 매출 | I9: 객단가
C10: 매출액(원) | D10: 매출건수(건) | E10: 매출액(원) | F10: 매출건수(건) | G10: 총 매출액(원) | H10: 총 매출건수(건)
C11: 2189300 | D11: 152 | E11: =SUM(E55:I56) -> 253800 | F11: =SUM(E53:I54) -> 13 | G11: =C11+E11 -> 2443100 | H11: =D11+F11 -> 165 | I11: =G11/H11 -> 14806.667
A12: 2. 제품 판매량 | B12: 제품명 | C12: 생산량(ea) | D12: 손실량(ea) | E12: 시식량(ea) | F12: 기타(ea) In (+) / Out (-) | H12: 재고량(ea) | I12: 판매량(ea)
B13: 바게트 | C13: 65 | I13: =C13-D13-D14*1/2-E13-E14*1/2+F13-H13-H14*1/2-I14*1/2 -> 65
B14: 바게트(H)
B15: 화바게트 | C15: 24 | I15: =C15-D15-D16*1/2-E15-E16*1/2+F15-H15-H16*1/2-I16*1/2 -> 24
B16: 화바게트(H)
B17: 깜파뉴 | C17: 30 | I17: =C17-D17-D18*1/2-E17-E18*1/2+F17-H17-H18*1/2-I18*1/2 -> 30
B18: 깜파뉴(H)
B19: 식 빵 | C19: 16 | I19: =C19-D19-D20*1/2-E19-E20*1/2+F19-H19-H20*1/2-I20*1/2 -> 16
B20: 식 빵(H)
B21: 블랙올리브 | C21: 90 | E21: 2 | I21: =C21-D21-E21+F21-H21 -> 88
B22: 허 브 | C22: 100 | I22: =C22-D22-E22+F22-H22 -> 100
B23: 치아바타 | C23: 208 | E23: 1 | I23: =C23-D23-D24-E23-E24+F23+F24-H23-H24-I24 -> 204
B24: 화치아바타 | D24: 1 | E24: 2
B25: 크로아상 | C25: 45 | D25: 2 | I25: =C25-D25-E25+F25-H25 -> 43
B26: 뺑오쇼콜라 | C26: 41 | I26: =C26-D26-E26+F26-H26 -> 41
B27: 플레인 스콘 | C27: 32 | D27: 1 | I27: =C27-D27-E27+F27-H27 -> 31
B28: 크랜베리 스콘 | C28: 27 | I28: =C28-D28-E28+F28-H28 -> 27
B29: 브 레 첼 | C29: 10 | I29: =C29-D29-E29+F29-H29 -> 10
B30: 스틱브레첼 | C30: 104 | D30: 1 | I30: =C30-D30-D31-E30-E31+F30+F31-H30-H31-I31 -> 103
B31: 버터브레첼
B32: 호라산 통밀
B33: 호밀비트 | I33: 1
B34: 호밀후르츠 | I34: 8
B35: 구름빵
B36: 무화과 호밀스틱 | C36: 20 | I36: =C36-D36-E36+F36-H36 -> 20
B37: 봄날깜빠뉴 | I37: =C37-D37-D38*1/2-E37-E38*1/2+F37-H37-H38*1/2-I38*1/2 -> 0
B38: 봄날깜빠뉴(H)
B39: 여름메밀빵 | I39: =C39-D39-D40*1/2-E39-E40*1/2+F39-H39-H40*1/2-I40*1/2 -> 0
B40: 여름메밀빵(H)
B41: 가을애깜빠뉴 | I41: =C41-D41-D42*1/2-E41-E42*1/2+F41-H41-H42*1/2-I42*1/2 -> 0
B42: 가을애깜빠뉴(H)
B43: 슈톨렌
...

Sheet 14일
A1: 일 일 업 무 보 고 서
A2: 일 시 | C2: 2026년 2월 14일 (토요일) | E2: 확인 | F2: 작성자 | H2: 누계 매출액
A3: 지 점 명 | C3: 여의도 | D3: 점 | F3: 김윤희 | H3: =G11+'13일'!H3:I3 -> 28981900
E5: 날씨 | F5: 외부온도 | G5: 내부온도 | H5: 외부습도 | I5: 내부습도
E6: 맑음 | F6: 11 | G6: 26 | H6: 0.62 | I6: 0.28
A9: 1. 금일 매출 실적 | B9: 실적 | C9: POS 매출 | E9: POS 외 매출 | G9: 총 매출 | I9: 객단가
C10: 매출액(원) | D10: 매출건수(건) | E10: 매출액(원) | F10: 매출건수(건) | G10: 총 매출액(원) | H10: 총 매출건수(건)
C11: 1936500 | D11: 125 | E11: =SUM(E55:I56) -> 328900 | F11: =SUM(E53:I54) -> 9 | G11: =C11+E11 -> 2265400 | H11: =D11+F11 -> 134 | I11: =G11/H11 -> 16905.97
A12: 2. 제품 판매량 | B12: 제품명 | C12: 생산량(ea) | D12: 손실량(ea) | E12: 시식량(ea) | F12: 기타(ea) In (+) / Out (-) | H12: 재고량(ea) | I12: 판매량(ea)
B13: 바게트 | C13: 65 | I13: =C13-D13-D14*1/2-E13-E14*1/2+F13-H13-H14*1/2-I14*1/2 -> 65
B14: 바게트(H)
B15: 화바게트 | C15: 24 | I15: =C15-D15-D16*1/2-E15-E16*1/2+F15-H15-H16*1/2-I16*1/2 -> 24
B16: 화바게트(H)
B17: 깜파뉴 | C17: 28 | D17: 3 | I17: =C17-D17-D18*1/2-E17-E18*1/2+F17-H17-H18*1/2-I18*1/2 -> 23.5
B18: 깜파뉴(H) | D18: 2 | E18: 1
B19: 식 빵 | C19: 16 | I19: =C19-D19-D20*1/2-E19-E20*1/2+F19-H19-H20*1/2-I20*1/2 -> 16
B20: 식 빵(H)
B21: 블랙올리브 | C21: 82 | E21: 1 | H21: 6 | I21: =C21-D21-E21+F21-H21 -> 75
B22: 허 브 | C22: 57 | D22: 2 | H22: 8 | I22: =C22-D22-E22+F22-H22 -> 47
B23: 치아바타 | C23: 183 | D23: 1 | E23: 2 | H23: 20 | I23: =C23-D23-D24-E23-E24+F23+F24-H23-H24-I24 -> 156
B24: 화치아바타 | D24: 1 | H24: 3
B25: 크로아상 | C25: 35 | I25: =C25-D25-E25+F25-H25 -> 35
B26: 뺑오쇼콜라 | C26: 55 | I26: =C26-D26-E26+F26-H26 -> 55
B27: 플레인 스콘 | C27: 29 | D27: 2 | I27: =C27-D27-E27+F27-H27 -> 27
B28: 크랜베리 스콘 | C28: 45 | D28: 8 | I28: =C28-D28-E28+F28-H28 -> 37
B29: 브 레 첼 | C29: 10 | I29: =C29-D29-E29+F29-H29 -> 10
B30: 스틱브레첼 | C30: 102 | D30: 1 | I30: =C30-D30-D31-E30-E31+F30+F31-H30-H31-I31 -> 101
B31: 버터브레첼
B32: 호라산 통밀
B33: 호밀비트
B34: 호밀후르츠 | I34: 2
B35: 구름빵 | I35: 8
B36: 무화과 호밀스틱 | C36: 20 | I36: =C36-D36-E36+F36-H36 -> 20
B37: 봄날깜빠뉴 | I37: =C37-D37-D38*1/2-E37-E38*1/2+F37-H37-H38*1/2-I38*1/2 -> 0
B38: 봄날깜빠뉴(H)
B39: 여름메밀빵 | I39: =C39-D39-D40*1/2-E39-E40*1/2+F39-H39-H40*1/2-I40*1/2 -> 0
B40: 여름메밀빵(H)
B41: 가을애깜빠뉴 | I41: =C41-D41-D42*1/2-E41-E42*1/2+F41-H41-H42*1/2-I42*1/2 -> 0
B42: 가을애깜빠뉴(H)
B43: 슈톨렌
...

Sheet 15일
A1: 일 일 업 무 보 고 서
A2: 일 시 | C2: 2026년 2월 15일 ( 일요일) | E2: 확인 | F2: 작성자 | H2: 누계 매출액
A3: 지 점 명 | C3: 여의도 | D3: 점 | F3: 유준모 | H3: =G11+'14일'!H3:I3 -> 30349100
E5: 날씨 | F5: 외부온도 | G5: 내부온도 | H5: 외부습도 | I5: 내부습도
E6: 흐림 | F6: 10 | G6: 26 | H6: 0.31 | I6: 0.27
A9: 1. 금일 매출 실적 | B9: 실적 | C9: POS 매출 | E9: POS 외 매출 | G9: 총 매출 | I9: 객단가
C10: 매출액(원) | D10: 매출건수(건) | E10: 매출액(원) | F10: 매출건수(건) | G10: 총 매출액(원) | H10: 총 매출건수(건)
C11: 1180900 | D11: 70 | E11: =SUM(E55:I56) -> 186300 | F11: =SUM(E53:I54) -> 9 | G11: =C11+E11 -> 1367200 | H11: =D11+F11 -> 79 | I11: =G11/H11 -> 17306.329
A12: 2. 제품 판매량 | B12: 제품명 | C12: 생산량(ea) | D12: 손실량(ea) | E12: 시식량(ea) | F12: 기타(ea) In (+) / Out (-) | H12: 재고량(ea) | I12: 판매량(ea)
B13: 바게트 | C13: 35 | I13: =C13-D13-D14*1/2-E13-E14*1/2+F13-H13-H14*1/2-I14*1/2 -> 35
B14: 바게트(H)
B15: 화바게트 | C15: 25 | I15: =C15-D15-D16*1/2-E15-E16*1/2+F15-H15-H16*1/2-I16*1/2 -> 25
B16: 화바게트(H)
B17: 깜파뉴 | C17: 38 | D17: 4 | I17: =C17-D17-D18*1/2-E17-E18*1/2+F17-H17-H18*1/2-I18*1/2 -> 34
B18: 깜파뉴(H)
B19: 식 빵 | C19: 16 | I19: =C19-D19-D20*1/2-E19-E20*1/2+F19-H19-H20*1/2-I20*1/2 -> 16
B20: 식 빵(H)
B21: 블랙올리브 | C21: 95 | D21: 2 | H21: 9 | I21: =C21-D21-E21+F21-H21 -> 84
B22: 허 브 | C22: 40 | E22: 2 | H22: 2 | I22: =C22-D22-E22+F22-H22 -> 36
B23: 치아바타 | C23: 184 | E23: 2 | H23: 28 | I23: =C23-D23-D24-E23-E24+F23+F24-H23-H24-I24 -> 140
B24: 화치아바타 | D24: 1 | E24: 1 | H24: 12
B25: 크로아상 | C25: 35 | H25: 13 | I25: =C25-D25-E25+F25-H25 -> 22
B26: 뺑오쇼콜라 | C26: 55 | D26: 1 | I26: =C26-D26-E26+F26-H26 -> 54
B27: 플레인 스콘 | C27: 29 | D27: 1 | H27: 1 | I27: =C27-D27-E27+F27-H27 -> 27
B28: 크랜베리 스콘 | C28: 45 | D28: 1 | H28: 2 | I28: =C28-D28-E28+F28-H28 -> 42
B29: 브 레 첼 | C29: 10 | H29: 1 | I29: =C29-D29-E29+F29-H29 -> 9
B30: 스틱브레첼 | C30: 160 | H30: 29 | I30: =C30-D30-D31-E30-E31+F30+F31-H30-H31-I31 -> 131
B31: 버터브레첼
B32: 호라산 통밀
B33: 호밀비트
B34: 호밀후르츠
B35: 구름빵
B36: 무화과 호밀스틱 | C36: 20 | D36: 1 | I36: =C36-D36-E36+F36-H36 -> 19
B37: 봄날깜빠뉴 | I37: =C37-D37-D38*1/2-E37-E38*1/2+F37-H37-H38*1/2-I38*1/2 -> 0
B38: 봄날깜빠뉴(H)
B39: 여름메밀빵 | I39: =C39-D39-D40*1/2-E39-E40*1/2+F39-H39-H40*1/2-I40*1/2 -> 0
B40: 여름메밀빵(H)
B41: 가을애깜빠뉴 | I41: =C41-D41-D42*1/2-E41-E42*1/2+F41-H41-H42*1/2-I42*1/2 -> 0
B42: 가을애깜빠뉴(H)
B43: 슈톨렌
...

Sheet 16일
A1: 일 일 업 무 보 고 서
A2: 일 시 | C2: 202 년 월 일 ( 요일) | E2: 확인 | F2: 작성자 | H2: 누계 매출액
A3: 지 점 명 | D3: 점 | H3: =G11+'15일'!H3:I3 -> 30349100
E5: 날씨 | F5: 외부온도 | G5: 내부온도 | H5: 외부습도 | I5: 내부습도
A9: 1. 금일 매출 실적 | B9: 실적 | C9: POS 매출 | E9: POS 외 매출 | G9: 총 매출 | I9: 객단가
C10: 매출액(원) | D10: 매출건수(건) | E10: 매출액(원) | F10: 매출건수(건) | G10: 총 매출액(원) | H10: 총 매출건수(건)
E11: =SUM(E55:I56) -> 0 | F11: =SUM(E53:I54) -> 0 | G11: =C11+E11 -> 0 | H11: =D11+F11 -> 0 | I11: =G11/H11 -> #DIV/0!
A12: 2. 제품 판매량 | B12: 제품명 | C12: 생산량(ea) | D12: 손실량(ea) | E12: 시식량(ea) | F12: 기타(ea) In (+) / Out (-) | H12: 재고량(ea) | I12: 판매량(ea)
B13: 바게트 | I13: =C13-D13-D14*1/2-E13-E14*1/2+F13-H13-H14*1/2-I14*1/2 -> 0
B14: 바게트(H)
B15: 화바게트 | I15: =C15-D15-D16*1/2-E15-E16*1/2+F15-H15-H16*1/2-I16*1/2 -> 0
B16: 화바게트(H)
B17: 깜파뉴 | I17: =C17-D17-D18*1/2-E17-E18*1/2+F17-H17-H18*1/2-I18*1/2 -> 0
B18: 깜파뉴(H)
B19: 식 빵 | I19: =C19-D19-D20*1/2-E19-E20*1/2+F19-H19-H20*1/2-I20*1/2 -> 0
B20: 식 빵(H)
B21: 블랙올리브 | I21: =C21-D21-E21+F21-H21 -> 0
B22: 허 브 | I22: =C22-D22-E22+F22-H22 -> 0
B23: 치아바타 | I23: =C23-D23-D24-E23-E24+F23+F24-H23-H24-I24 -> 0
B24: 화치아바타
B25: 크로아상 | I25: =C25-D25-E25+F25-H25 -> 0
B26: 뺑오쇼콜라 | I26: =C26-D26-E26+F26-H26 -> 0
B27: 플레인 스콘 | I27: =C27-D27-E27+F27-H27 -> 0
B28: 크랜베리 스콘 | I28: =C28-D28-E28+F28-H28 -> 0
B29: 브 레 첼 | I29: =C29-D29-E29+F29-H29 -> 0
B30: 스틱브레첼 | I30: =C30-D30-D31-E30-E31+F30+F31-H30-H31-I31 -> 0
B31: 버터브레첼
B32: 호라산 통밀
B33: 호밀비트
B34: 호밀후르츠
B35: 구름빵
B36: 무화과 호밀스틱 | I36: =C36-D36-E36+F36-H36 -> 0
B37: 봄날깜빠뉴 | I37: =C37-D37-D38*1/2-E37-E38*1/2+F37-H37-H38*1/2-I38*1/2 -> 0
B38: 봄날깜빠뉴(H)
B39: 여름메밀빵 | I39: =C39-D39-D40*1/2-E39-E40*1/2+F39-H39-H40*1/2-I40*1/2 -> 0
B40: 여름메밀빵(H)
B41: 가을애깜빠뉴 | I41: =C41-D41-D42*1/2-E41-E42*1/2+F41-H41-H42*1/2-I42*1/2 -> 0
B42: 가을애깜빠뉴(H)
B43: 슈톨렌
B44: 미니파네토네(여름)
...

Sheet 17일
A1: 일 일 업 무 보 고 서
A2: 일 시 | C2: 202 년 월 일 ( 요일) | E2: 확인 | F2: 작성자 | H2: 누계 매출액
A3: 지 점 명 | D3: 점 | H3: =G11+'16일'!H3:I3 -> 30349100
E5: 날씨 | F5: 외부온도 | G5: 내부온도 | H5: 외부습도 | I5: 내부습도
A9: 1. 금일 매출 실적 | B9: 실적 | C9: POS 매출 | E9: POS 외 매출 | G9: 총 매출 | I9: 객단가
C10: 매출액(원) | D10: 매출건수(건) | E10: 매출액(원) | F10: 매출건수(건) | G10: 총 매출액(원) | H10: 총 매출건수(건)
E11: =SUM(E55:I56) -> 0 | F11: =SUM(E53:I54) -> 0 | G11: =C11+E11 -> 0 | H11: =D11+F11 -> 0 | I11: =G11/H11 -> #DIV/0!
A12: 2. 제품 판매량 | B12: 제품명 | C12: 생산량(ea) | D12: 손실량(ea) | E12: 시식량(ea) | F12: 기타(ea) In (+) / Out (-) | H12: 재고량(ea) | I12: 판매량(ea)
B13: 바게트 | I13: =C13-D13-D14*1/2-E13-E14*1/2+F13-H13-H14*1/2-I14*1/2 -> 0
B14: 바게트(H)
B15: 화바게트 | I15: =C15-D15-D16*1/2-E15-E16*1/2+F15-H15-H16*1/2-I16*1/2 -> 0
B16: 화바게트(H)
B17: 깜파뉴 | I17: =C17-D17-D18*1/2-E17-E18*1/2+F17-H17-H18*1/2-I18*1/2 -> 0
B18: 깜파뉴(H)
B19: 식 빵 | I19: =C19-D19-D20*1/2-E19-E20*1/2+F19-H19-H20*1/2-I20*1/2 -> 0
B20: 식 빵(H)
B21: 블랙올리브 | I21: =C21-D21-E21+F21-H21 -> 0
B22: 허 브 | I22: =C22-D22-E22+F22-H22 -> 0
B23: 치아바타 | I23: =C23-D23-D24-E23-E24+F23+F24-H23-H24-I24 -> 0
B24: 화치아바타
B25: 크로아상 | I25: =C25-D25-E25+F25-H25 -> 0
B26: 뺑오쇼콜라 | I26: =C26-D26-E26+F26-H26 -> 0
B27: 플레인 스콘 | I27: =C27-D27-E27+F27-H27 -> 0
B28: 크랜베리 스콘 | I28: =C28-D28-E28+F28-H28 -> 0
B29: 브 레 첼 | I29: =C29-D29-E29+F29-H29 -> 0
B30: 스틱브레첼 | I30: =C30-D30-D31-E30-E31+F30+F31-H30-H31-I31 -> 0
B31: 버터브레첼
B32: 호라산 통밀
B33: 호밀비트
B34: 호밀후르츠
B35: 구름빵
B36: 무화과 호밀스틱 | I36: =C36-D36-E36+F36-H36 -> 0
B37: 봄날깜빠뉴 | I37: =C37-D37-D38*1/2-E37-E38*1/2+F37-H37-H38*1/2-I38*1/2 -> 0
B38: 봄날깜빠뉴(H)
B39: 여름메밀빵 | I39: =C39-D39-D40*1/2-E39-E40*1/2+F39-H39-H40*1/2-I40*1/2 -> 0
B40: 여름메밀빵(H)
B41: 가을애깜빠뉴 | I41: =C41-D41-D42*1/2-E41-E42*1/2+F41-H41-H42*1/2-I42*1/2 -> 0
B42: 가을애깜빠뉴(H)
B43: 슈톨렌
B44: 미니파네토네(여름)
...

Sheet 18일
A1: 일 일 업 무 보 고 서
A2: 일 시 | C2: 2026 년 2월 18 일 ( 수요일) | E2: 확인 | F2: 작성자 | H2: 누계 매출액
A3: 지 점 명 | C3: 여의도 | D3: 점 | F3: 김세은 | H3: =G11+'17일'!H3:I3 -> 32032900
E5: 날씨 | F5: 외부온도 | G5: 내부온도 | H5: 외부습도 | I5: 내부습도
E6: 맑음 | F6: 5 | G6: 23 | H6: 0.34 | I6: 0.25
A9: 1. 금일 매출 실적 | B9: 실적 | C9: POS 매출 | E9: POS 외 매출 | G9: 총 매출 | I9: 객단가
C10: 매출액(원) | D10: 매출건수(건) | E10: 매출액(원) | F10: 매출건수(건) | G10: 총 매출액(원) | H10: 총 매출건수(건)
C11: 1269100 | D11: 83 | E11: =SUM(E55:I56) -> 414700 | F11: =SUM(E53:I54) -> 19 | G11: =C11+E11 -> 1683800 | H11: =D11+F11 -> 102 | I11: =G11/H11 -> 16507.843
A12: 2. 제품 판매량 | B12: 제품명 | C12: 생산량(ea) | D12: 손실량(ea) | E12: 시식량(ea) | F12: 기타(ea) In (+) / Out (-) | H12: 재고량(ea) | I12: 판매량(ea)
B13: 바게트 | C13: 19 | E13: 1 | I13: =C13-D13-D14*1/2-E13-E14*1/2+F13-H13-H14*1/2-I14*1/2 -> 18
B14: 바게트(H)
B15: 화바게트 | C15: 16 | I15: =C15-D15-D16*1/2-E15-E16*1/2+F15-H15-H16*1/2-I16*1/2 -> 16
B16: 화바게트(H)
B17: 깜파뉴 | C17: 18 | I17: =C17-D17-D18*1/2-E17-E18*1/2+F17-H17-H18*1/2-I18*1/2 -> 17.5
B18: 깜파뉴(H) | D18: 1
B19: 식 빵 | C19: 16 | H19: 1 | I19: =C19-D19-D20*1/2-E19-E20*1/2+F19-H19-H20*1/2-I20*1/2 -> 14.5
B20: 식 빵(H) | E20: 1
B21: 블랙올리브 | C21: 90 | E21: 3 | H21: 8 | I21: =C21-D21-E21+F21-H21 -> 79
B22: 허 브 | C22: 56 | D22: 3 | E22: 8 | H22: 10 | I22: =C22-D22-E22+F22-H22 -> 35
B23: 치아바타 | C23: 177 | D23: 1 | E23: 4 | H23: 8 | I23: =C23-D23-D24-E23-E24+F23+F24-H23-H24-I24 -> 154
B24: 화치아바타 | D24: 1 | E24: 2 | H24: 7
B25: 크로아상 | C25: 36 | D25: 1 | E25: 2 | H25: 3 | I25: =C25-D25-E25+F25-H25 -> 30
B26: 뺑오쇼콜라 | C26: 43 | D26: 1 | H26: 2 | I26: =C26-D26-E26+F26-H26 -> 40
B27: 플레인 스콘 | C27: 33 | H27: 5 | I27: =C27-D27-E27+F27-H27 -> 28
B28: 크랜베리 스콘 | C28: 43 | H28: 2 | I28: =C28-D28-E28+F28-H28 -> 41
B29: 브 레 첼 | C29: 10 | I29: =C29-D29-E29+F29-H29 -> 10
B30: 스틱브레첼 | C30: 89 | H30: 1 | I30: =C30-D30-D31-E30-E31+F30+F31-H30-H31-I31 -> 88
B31: 버터브레첼
B32: 호라산 통밀
B33: 호밀비트
B34: 호밀후르츠 | I34: 2
B35: 구름빵 | I35: 11
B36: 무화과 호밀스틱 | C36: 19 | I36: =C36-D36-E36+F36-H36 -> 19
B37: 봄날깜빠뉴 | I37: =C37-D37-D38*1/2-E37-E38*1/2+F37-H37-H38*1/2-I38*1/2 -> 0
B38: 봄날깜빠뉴(H)
B39: 여름메밀빵 | I39: =C39-D39-D40*1/2-E39-E40*1/2+F39-H39-H40*1/2-I40*1/2 -> 0
B40: 여름메밀빵(H)
B41: 가을애깜빠뉴 | I41: =C41-D41-D42*1/2-E41-E42*1/2+F41-H41-H42*1/2-I42*1/2 -> 0
B42: 가을애깜빠뉴(H)
B43: 슈톨렌
...

Sheet 19일
A1: 일 일 업 무 보 고 서
A2: 일 시 | C2: 2026년 2월 19일 ( 목요일) | E2: 확인 | F2: 작성자 | H2: 누계 매출액
A3: 지 점 명 | C3: 여의도 | D3: 점 | F3: 유준모 | H3: =G11+'18일'!H3:I3 -> 34858700
E5: 날씨 | F5: 외부온도 | G5: 내부온도 | H5: 외부습도 | I5: 내부습도
E6: 맑음 | F6: 6 | G6: 25 | H6: 0.34 | I6: 0.25
A9: 1. 금일 매출 실적 | B9: 실적 | C9: POS 매출 | E9: POS 외 매출 | G9: 총 매출 | I9: 객단가
C10: 매출액(원) | D10: 매출건수(건) | E10: 매출액(원) | F10: 매출건수(건) | G10: 총 매출액(원) | H10: 총 매출건수(건)
C11: 2186300 | D11: 153 | E11: =SUM(E55:I56) -> 639500 | F11: =SUM(E53:I54) -> 14 | G11: =C11+E11 -> 2825800 | H11: =D11+F11 -> 167 | I11: =G11/H11 -> 16920.958
A12: 2. 제품 판매량 | B12: 제품명 | C12: 생산량(ea) | D12: 손실량(ea) | E12: 시식량(ea) | F12: 기타(ea) In (+) / Out (-) | H12: 재고량(ea) | I12: 판매량(ea)
B13: 바게트 | C13: 40 | I13: =C13-D13-D14*1/2-E13-E14*1/2+F13-H13-H14*1/2-I14*1/2 -> 39.5
B14: 바게트(H) | D14: 1
B15: 화바게트 | C15: 37 | I15: =C15-D15-D16*1/2-E15-E16*1/2+F15-H15-H16*1/2-I16*1/2 -> 37
B16: 화바게트(H)
B17: 깜파뉴 | C17: 76 | D17: 1 | I17: =C17-D17-D18*1/2-E17-E18*1/2+F17-H17-H18*1/2-I18*1/2 -> 74
B18: 깜파뉴(H) | D18: 2
B19: 식 빵 | C19: 16 | I19: =C19-D19-D20*1/2-E19-E20*1/2+F19-H19-H20*1/2-I20*1/2 -> 16
B20: 식 빵(H)
B21: 블랙올리브 | C21: 89 | E21: 1 | I21: =C21-D21-E21+F21-H21 -> 88
B22: 허 브 | C22: 49 | I22: =C22-D22-E22+F22-H22 -> 49
B23: 치아바타 | C23: 190 | D23: 1 | I23: =C23-D23-D24-E23-E24+F23+F24-H23-H24-I24 -> 189
B24: 화치아바타
B25: 크로아상 | C25: 36 | I25: =C25-D25-E25+F25-H25 -> 36
B26: 뺑오쇼콜라 | C26: 43 | I26: =C26-D26-E26+F26-H26 -> 43
B27: 플레인 스콘 | C27: 33 | I27: =C27-D27-E27+F27-H27 -> 33
B28: 크랜베리 스콘 | C28: 33 | I28: =C28-D28-E28+F28-H28 -> 33
B29: 브 레 첼 | C29: 10 | I29: =C29-D29-E29+F29-H29 -> 10
B30: 스틱브레첼 | C30: 119 | D30: 3 | I30: =C30-D30-D31-E30-E31+F30+F31-H30-H31-I31 -> 116
B31: 버터브레첼
B32: 호라산 통밀
B33: 호밀비트
B34: 호밀후르츠 | I34: 2
B35: 구름빵 | E35: 2 | I35: 39
B36: 무화과 호밀스틱 | C36: 20 | I36: =C36-D36-E36+F36-H36 -> 20
B37: 봄날깜빠뉴 | I37: =C37-D37-D38*1/2-E37-E38*1/2+F37-H37-H38*1/2-I38*1/2 -> 0
B38: 봄날깜빠뉴(H)
B39: 여름메밀빵 | I39: =C39-D39-D40*1/2-E39-E40*1/2+F39-H39-H40*1/2-I40*1/2 -> 0
B40: 여름메밀빵(H)
B41: 가을애깜빠뉴 | I41: =C41-D41-D42*1/2-E41-E42*1/2+F41-H41-H42*1/2-I42*1/2 -> 0
B42: 가을애깜빠뉴(H)
B43: 슈톨렌
...

Sheet 20일
A1: 일 일 업 무 보 고 서
A2: 일 시 | C2: 2026 년 2월 20일 ( 금요일) | E2: 확인 | F2: 작성자 | H2: 누계 매출액
A3: 지 점 명 | C3: 여의도 | D3: 점 | F3: 정희주 | H3: =G11+'19일'!H3:I3 -> 37167200
E5: 날씨 | F5: 외부온도 | G5: 내부온도 | H5: 외부습도 | I5: 내부습도
E6: 맑음 | F6: 12 | G6: 24 | H6: 0.48 | I6: 0.26
A9: 1. 금일 매출 실적 | B9: 실적 | C9: POS 매출 | E9: POS 외 매출 | G9: 총 매출 | I9: 객단가
C10: 매출액(원) | D10: 매출건수(건) | E10: 매출액(원) | F10: 매출건수(건) | G10: 총 매출액(원) | H10: 총 매출건수(건)
C11: 2137300 | D11: 184 | E11: =SUM(E55:I56) -> 171200 | F11: =SUM(E53:I54) -> 10 | G11: =C11+E11 -> 2308500 | H11: =D11+F11 -> 194 | I11: =G11/H11 -> 11899.485
A12: 2. 제품 판매량 | B12: 제품명 | C12: 생산량(ea) | D12: 손실량(ea) | E12: 시식량(ea) | F12: 기타(ea) In (+) / Out (-) | H12: 재고량(ea) | I12: 판매량(ea)
B13: 바게트 | C13: 50 | I13: =C13-D13-D14*1/2-E13-E14*1/2+F13-H13-H14*1/2-I14*1/2 -> 50
B14: 바게트(H)
B15: 화바게트 | C15: 26 | I15: =C15-D15-D16*1/2-E15-E16*1/2+F15-H15-H16*1/2-I16*1/2 -> 26
B16: 화바게트(H)
B17: 깜파뉴 | C17: 20 | I17: =C17-D17-D18*1/2-E17-E18*1/2+F17-H17-H18*1/2-I18*1/2 -> 19.5
B18: 깜파뉴(H) | E18: 1
B19: 식 빵 | C19: 16 | I19: =C19-D19-D20*1/2-E19-E20*1/2+F19-H19-H20*1/2-I20*1/2 -> 16
B20: 식 빵(H)
B21: 블랙올리브 | C21: 82 | I21: =C21-D21-E21+F21-H21 -> 82
B22: 허 브 | C22: 37 | D22: 1 | E22: 1 | H22: 6 | I22: =C22-D22-E22+F22-H22 -> 29
B23: 치아바타 | C23: 81 | D23: 2 | E23: 1 | I23: =C23-D23-D24-E23-E24+F23+F24-H23-H24-I24 -> 76
B24: 화치아바타 | E24: 2
B25: 크로아상 | C25: 36 | H25: 2 | I25: =C25-D25-E25+F25-H25 -> 34
B26: 뺑오쇼콜라 | C26: 43 | I26: =C26-D26-E26+F26-H26 -> 43
B27: 플레인 스콘 | C27: 29 | D27: 2 | I27: =C27-D27-E27+F27-H27 -> 27
B28: 크랜베리 스콘 | C28: 44 | D28: 1 | I28: =C28-D28-E28+F28-H28 -> 43
B29: 브 레 첼 | C29: 10 | D29: 1 | I29: =C29-D29-E29+F29-H29 -> 9
B30: 스틱브레첼 | C30: 107 | D30: 1 | E30: 4 | I30: =C30-D30-D31-E30-E31+F30+F31-H30-H31-I31 -> 102
B31: 버터브레첼
B32: 호라산 통밀
B33: 호밀비트
B34: 호밀후르츠 | I34: 2
B35: 구름빵 | C35: 32 | I35: 24
B36: 무화과 호밀스틱 | C36: 20 | D36: 1 | I36: =C36-D36-E36+F36-H36 -> 19
B37: 봄날깜빠뉴 | I37: =C37-D37-D38*1/2-E37-E38*1/2+F37-H37-H38*1/2-I38*1/2 -> 0
B38: 봄날깜빠뉴(H)
B39: 여름메밀빵 | I39: =C39-D39-D40*1/2-E39-E40*1/2+F39-H39-H40*1/2-I40*1/2 -> 0
B40: 여름메밀빵(H)
B41: 가을애깜빠뉴 | I41: =C41-D41-D42*1/2-E41-E42*1/2+F41-H41-H42*1/2-I42*1/2 -> 0
B42: 가을애깜빠뉴(H)
B43: 슈톨렌
...

Sheet 21일
A1: 일 일 업 무 보 고 서
A2: 일 시 | C2: 2026년 2월 21일 (토요일) | E2: 확인 | F2: 작성자 | H2: 누계 매출액
A3: 지 점 명 | C3: 여의도 | D3: 점 | F3: 김윤희 | H3: =G11+'20일'!H3:I3 -> 39566700
E5: 날씨 | F5: 외부온도 | G5: 내부온도 | H5: 외부습도 | I5: 내부습도
E6: 맑음 | F6: 17 | G6: 26 | H6: 0.29 | I6: 0.26
A9: 1. 금일 매출 실적 | B9: 실적 | C9: POS 매출 | E9: POS 외 매출 | G9: 총 매출 | I9: 객단가
C10: 매출액(원) | D10: 매출건수(건) | E10: 매출액(원) | F10: 매출건수(건) | G10: 총 매출액(원) | H10: 총 매출건수(건)
C11: 2016400 | D11: 158 | E11: =SUM(E55:I56) -> 383100 | F11: =SUM(E53:I54) -> 13 | G11: =C11+E11 -> 2399500 | H11: =D11+F11 -> 171 | I11: =G11/H11 -> 14032.164
A12: 2. 제품 판매량 | B12: 제품명 | C12: 생산량(ea) | D12: 손실량(ea) | E12: 시식량(ea) | F12: 기타(ea) In (+) / Out (-) | H12: 재고량(ea) | I12: 판매량(ea)
B13: 바게트 | C13: 53 | I13: =C13-D13-D14*1/2-E13-E14*1/2+F13-H13-H14*1/2-I14*1/2 -> 53
B14: 바게트(H)
B15: 화바게트 | C15: 23 | I15: =C15-D15-D16*1/2-E15-E16*1/2+F15-H15-H16*1/2-I16*1/2 -> 23
B16: 화바게트(H)
B17: 깜파뉴 | C17: 39 | I17: =C17-D17-D18*1/2-E17-E18*1/2+F17-H17-H18*1/2-I18*1/2 -> 39
B18: 깜파뉴(H)
B19: 식 빵 | C19: 16 | I19: =C19-D19-D20*1/2-E19-E20*1/2+F19-H19-H20*1/2-I20*1/2 -> 16
B20: 식 빵(H)
B21: 블랙올리브 | C21: 102 | I21: =C21-D21-E21+F21-H21 -> 102
B22: 허 브 | C22: 60 | I22: =C22-D22-E22+F22-H22 -> 60
B23: 치아바타 | C23: 219 | D23: 1 | E23: 1 | I23: =C23-D23-D24-E23-E24+F23+F24-H23-H24-I24 -> 214
B24: 화치아바타 | E24: 3
B25: 크로아상 | C25: 48 | I25: =C25-D25-E25+F25-H25 -> 48
B26: 뺑오쇼콜라 | C26: 43 | I26: =C26-D26-E26+F26-H26 -> 43
B27: 플레인 스콘 | C27: 32 | D27: 1 | I27: =C27-D27-E27+F27-H27 -> 31
B28: 크랜베리 스콘 | C28: 40 | D28: 1 | I28: =C28-D28-E28+F28-H28 -> 39
B29: 브 레 첼 | C29: 10 | I29: =C29-D29-E29+F29-H29 -> 10
B30: 스틱브레첼 | C30: 80 | I30: =C30-D30-D31-E30-E31+F30+F31-H30-H31-I31 -> 80
B31: 버터브레첼
B32: 호라산 통밀
B33: 호밀비트
B34: 호밀후르츠 | I34: 2
B35: 구름빵 | E35: 1 | I35: 36
B36: 무화과 호밀스틱 | C36: 20 | I36: =C36-D36-E36+F36-H36 -> 20
B37: 봄날깜빠뉴 | I37: =C37-D37-D38*1/2-E37-E38*1/2+F37-H37-H38*1/2-I38*1/2 -> 0
B38: 봄날깜빠뉴(H)
B39: 여름메밀빵 | I39: =C39-D39-D40*1/2-E39-E40*1/2+F39-H39-H40*1/2-I40*1/2 -> 0
B40: 여름메밀빵(H)
B41: 가을애깜빠뉴 | I41: =C41-D41-D42*1/2-E41-E42*1/2+F41-H41-H42*1/2-I42*1/2 -> 0
B42: 가을애깜빠뉴(H)
B43: 슈톨렌
...

Sheet 22일
A1: 일 일 업 무 보 고 서
A2: 일 시 | C2: 2026 년 2월 22일 ( 일요일) | E2: 확인 | F2: 작성자 | H2: 누계 매출액
A3: 지 점 명 | C3: 여의도 | D3: 점 | F3: 정희주 | H3: =G11+'21일'!H3:I3 -> 40942100
E5: 날씨 | F5: 외부온도 | G5: 내부온도 | H5: 외부습도 | I5: 내부습도
E6: 흐림 | F6: 9 | G6: 25 | H6: 0.39 | I6: 0.27
A9: 1. 금일 매출 실적 | B9: 실적 | C9: POS 매출 | E9: POS 외 매출 | G9: 총 매출 | I9: 객단가
C10: 매출액(원) | D10: 매출건수(건) | E10: 매출액(원) | F10: 매출건수(건) | G10: 총 매출액(원) | H10: 총 매출건수(건)
C11: 1125700 | D11: 79 | E11: =SUM(E55:I56) -> 249700 | F11: =SUM(E53:I54) -> 11 | G11: =C11+E11 -> 1375400 | H11: =D11+F11 -> 90 | I11: =G11/H11 -> 15282.222
A12: 2. 제품 판매량 | B12: 제품명 | C12: 생산량(ea) | D12: 손실량(ea) | E12: 시식량(ea) | F12: 기타(ea) In (+) / Out (-) | H12: 재고량(ea) | I12: 판매량(ea)
B13: 바게트 | C13: 39 | I13: =C13-D13-D14*1/2-E13-E14*1/2+F13-H13-H14*1/2-I14*1/2 -> 39
B14: 바게트(H)
B15: 화바게트 | C15: 23 | I15: =C15-D15-D16*1/2-E15-E16*1/2+F15-H15-H16*1/2-I16*1/2 -> 23
B16: 화바게트(H)
B17: 깜파뉴 | C17: 28 | H17: 2 | I17: =C17-D17-D18*1/2-E17-E18*1/2+F17-H17-H18*1/2-I18*1/2 -> 26
B18: 깜파뉴(H)
B19: 식 빵 | C19: 12 | I19: =C19-D19-D20*1/2-E19-E20*1/2+F19-H19-H20*1/2-I20*1/2 -> 12
B20: 식 빵(H)
B21: 블랙올리브 | C21: 82 | I21: =C21-D21-E21+F21-H21 -> 82
B22: 허 브 | C22: 47 | H22: 14 | I22: =C22-D22-E22+F22-H22 -> 33
B23: 치아바타 | C23: 171 | I23: =C23-D23-D24-E23-E24+F23+F24-H23-H24-I24 -> 171
B24: 화치아바타
B25: 크로아상 | C25: 36 | H25: 2 | I25: =C25-D25-E25+F25-H25 -> 34
B26: 뺑오쇼콜라 | C26: 30 | I26: =C26-D26-E26+F26-H26 -> 30
B27: 플레인 스콘 | C27: 33 | I27: =C27-D27-E27+F27-H27 -> 33
B28: 크랜베리 스콘 | C28: 45 | H28: 16 | I28: =C28-D28-E28+F28-H28 -> 29
B29: 브 레 첼 | C29: 10 | I29: =C29-D29-E29+F29-H29 -> 10
B30: 스틱브레첼 | C30: 108 | I30: =C30-D30-D31-E30-E31+F30+F31-H30-H31-I31 -> 108
B31: 버터브레첼
B32: 호라산 통밀
B33: 호밀비트
B34: 호밀후르츠
B35: 구름빵
B36: 무화과 호밀스틱 | C36: 20 | I36: =C36-D36-E36+F36-H36 -> 20
B37: 봄날깜빠뉴 | I37: =C37-D37-D38*1/2-E37-E38*1/2+F37-H37-H38*1/2-I38*1/2 -> 0
B38: 봄날깜빠뉴(H)
B39: 여름메밀빵 | I39: =C39-D39-D40*1/2-E39-E40*1/2+F39-H39-H40*1/2-I40*1/2 -> 0
B40: 여름메밀빵(H)
B41: 가을애깜빠뉴 | I41: =C41-D41-D42*1/2-E41-E42*1/2+F41-H41-H42*1/2-I42*1/2 -> 0
B42: 가을애깜빠뉴(H)
B43: 슈톨렌
...

Sheet 23일
A1: 일 일 업 무 보 고 서
A2: 일 시 | C2: 2026 년 2월 23일 ( 월요일) | E2: 확인 | F2: 작성자 | H2: 누계 매출액
A3: 지 점 명 | C3: 여의도 | D3: 점 | F3: 정희주 | H3: =G11+'22일'!H3:I3 -> 43075100
E5: 날씨 | F5: 외부온도 | G5: 내부온도 | H5: 외부습도 | I5: 내부습도
E6: 흐림 | F6: 5 | G6: 23 | H6: 0.24 | I6: 0.25
A9: 1. 금일 매출 실적 | B9: 실적 | C9: POS 매출 | E9: POS 외 매출 | G9: 총 매출 | I9: 객단가
C10: 매출액(원) | D10: 매출건수(건) | E10: 매출액(원) | F10: 매출건수(건) | G10: 총 매출액(원) | H10: 총 매출건수(건)
C11: 1745100 | D11: 146 | E11: =SUM(E55:I56) -> 387900 | F11: =SUM(E53:I54) -> 20 | G11: =C11+E11 -> 2133000 | H11: =D11+F11 -> 166 | I11: =G11/H11 -> 12849.398
A12: 2. 제품 판매량 | B12: 제품명 | C12: 생산량(ea) | D12: 손실량(ea) | E12: 시식량(ea) | F12: 기타(ea) In (+) / Out (-) | H12: 재고량(ea) | I12: 판매량(ea)
B13: 바게트 | C13: 25 | H13: 9 | I13: =C13-D13-D14*1/2-E13-E14*1/2+F13-H13-H14*1/2-I14*1/2 -> 16
B14: 바게트(H)
B15: 화바게트 | C15: 25 | H15: 9 | I15: =C15-D15-D16*1/2-E15-E16*1/2+F15-H15-H16*1/2-I16*1/2 -> 16
B16: 화바게트(H)
B17: 깜파뉴 | C17: 32 | I17: =C17-D17-D18*1/2-E17-E18*1/2+F17-H17-H18*1/2-I18*1/2 -> 31.5
B18: 깜파뉴(H) | E18: 1
B19: 식 빵 | C19: 16 | I19: =C19-D19-D20*1/2-E19-E20*1/2+F19-H19-H20*1/2-I20*1/2 -> 16
B20: 식 빵(H)
B21: 블랙올리브 | C21: 83 | E21: 1 | H21: 4 | I21: =C21-D21-E21+F21-H21 -> 78
B22: 허 브 | C22: 73 | H22: 6 | I22: =C22-D22-E22+F22-H22 -> 67
B23: 치아바타 | C23: 230 | H23: 12 | I23: =C23-D23-D24-E23-E24+F23+F24-H23-H24-I24 -> 218
B24: 화치아바타
B25: 크로아상 | C25: 24 | I25: =C25-D25-E25+F25-H25 -> 24
B26: 뺑오쇼콜라 | C26: 38 | I26: =C26-D26-E26+F26-H26 -> 38
B27: 플레인 스콘 | C27: 29 | I27: =C27-D27-E27+F27-H27 -> 29
B28: 크랜베리 스콘 | C28: 39 | I28: =C28-D28-E28+F28-H28 -> 39
B29: 브 레 첼 | C29: 10 | E29: 1 | I29: =C29-D29-E29+F29-H29 -> 9
B30: 스틱브레첼 | C30: 102 | D30: 1 | H30: 7 | I30: =C30-D30-D31-E30-E31+F30+F31-H30-H31-I31 -> 94
B31: 버터브레첼
B32: 호라산 통밀
B33: 호밀비트
B34: 호밀후르츠 | I34: 2
B35: 구름빵 | E35: 1 | I35: 21
B36: 무화과 호밀스틱 | C36: 20 | I36: =C36-D36-E36+F36-H36 -> 20
B37: 봄날깜빠뉴 | I37: =C37-D37-D38*1/2-E37-E38*1/2+F37-H37-H38*1/2-I38*1/2 -> 0
B38: 봄날깜빠뉴(H)
B39: 여름메밀빵 | I39: =C39-D39-D40*1/2-E39-E40*1/2+F39-H39-H40*1/2-I40*1/2 -> 0
B40: 여름메밀빵(H)
B41: 가을애깜빠뉴 | I41: =C41-D41-D42*1/2-E41-E42*1/2+F41-H41-H42*1/2-I42*1/2 -> 0
B42: 가을애깜빠뉴(H)
B43: 슈톨렌
...

Sheet 24일
A1: 일 일 업 무 보 고 서
A2: 일 시 | C2: 2026년 2월 24일 (화요일) | E2: 확인 | F2: 작성자 | H2: 누계 매출액
A3: 지 점 명 | C3: 여의도 | D3: 점 | F3: 김윤희 | H3: =G11+'23일'!H3:I3 -> 45289700
E5: 날씨 | F5: 외부온도 | G5: 내부온도 | H5: 외부습도 | I5: 내부습도
E6: 흐림 | F6: 3 | G6: 24 | H6: 0.3 | I6: 0.25
A9: 1. 금일 매출 실적 | B9: 실적 | C9: POS 매출 | E9: POS 외 매출 | G9: 총 매출 | I9: 객단가
C10: 매출액(원) | D10: 매출건수(건) | E10: 매출액(원) | F10: 매출건수(건) | G10: 총 매출액(원) | H10: 총 매출건수(건)
C11: 2030900 | D11: 156 | E11: =SUM(E55:I56) -> 183700 | F11: =SUM(E53:I54) -> 10 | G11: =C11+E11 -> 2214600 | H11: =D11+F11 -> 166 | I11: =G11/H11 -> 13340.964
A12: 2. 제품 판매량 | B12: 제품명 | C12: 생산량(ea) | D12: 손실량(ea) | E12: 시식량(ea) | F12: 기타(ea) In (+) / Out (-) | H12: 재고량(ea) | I12: 판매량(ea)
B13: 바게트 | C13: 20 | I13: =C13-D13-D14*1/2-E13-E14*1/2+F13-H13-H14*1/2-I14*1/2 -> 20
B14: 바게트(H)
B15: 화바게트 | C15: 15 | I15: =C15-D15-D16*1/2-E15-E16*1/2+F15-H15-H16*1/2-I16*1/2 -> 15
B16: 화바게트(H)
B17: 깜파뉴 | C17: 16 | I17: =C17-D17-D18*1/2-E17-E18*1/2+F17-H17-H18*1/2-I18*1/2 -> 15
B18: 깜파뉴(H) | D18: 1 | E18: 1
B19: 식 빵 | C19: 8 | I19: =C19-D19-D20*1/2-E19-E20*1/2+F19-H19-H20*1/2-I20*1/2 -> 8
B20: 식 빵(H)
B21: 블랙올리브 | C21: 61 | I21: =C21-D21-E21+F21-H21 -> 61
B22: 허 브 | C22: 27 | I22: =C22-D22-E22+F22-H22 -> 27
B23: 치아바타 | C23: 117 | E23: 1 | I23: =C23-D23-D24-E23-E24+F23+F24-H23-H24-I24 -> 113
B24: 화치아바타 | E24: 3
B25: 크로아상 | C25: 23 | I25: =C25-D25-E25+F25-H25 -> 23
B26: 뺑오쇼콜라 | C26: 21 | I26: =C26-D26-E26+F26-H26 -> 21
B27: 플레인 스콘 | C27: 26 | D27: 1 | I27: =C27-D27-E27+F27-H27 -> 25
B28: 크랜베리 스콘 | C28: 41 | D28: 1 | I28: =C28-D28-E28+F28-H28 -> 40
B29: 브 레 첼 | C29: 5 | I29: =C29-D29-E29+F29-H29 -> 5
B30: 스틱브레첼 | C30: 77 | D30: 2 | I30: =C30-D30-D31-E30-E31+F30+F31-H30-H31-I31 -> 75
B31: 버터브레첼
B32: 호라산 통밀
B33: 호밀비트
B34: 호밀후르츠 | I34: 2
B35: 구름빵 | I35: 28
B36: 무화과 호밀스틱 | I36: =C36-D36-E36+F36-H36 -> 0
B37: 봄날깜빠뉴 | I37: =C37-D37-D38*1/2-E37-E38*1/2+F37-H37-H38*1/2-I38*1/2 -> 0
B38: 봄날깜빠뉴(H)
B39: 여름메밀빵 | I39: =C39-D39-D40*1/2-E39-E40*1/2+F39-H39-H40*1/2-I40*1/2 -> 0
B40: 여름메밀빵(H)
B41: 가을애깜빠뉴 | I41: =C41-D41-D42*1/2-E41-E42*1/2+F41-H41-H42*1/2-I42*1/2 -> 0
B42: 가을애깜빠뉴(H)
B43: 슈톨렌
...

Sheet 25일
A1: 일 일 업 무 보 고 서
A2: 일 시 | C2: 2026 년 2월 25일 ( 수요일) | E2: 확인 | F2: 작성자 | H2: 누계 매출액
A3: 지 점 명 | C3: 여의도 | D3: 점 | F3: 정희주 | H3: =G11+'24일'!H3:I3 -> 47346800
E5: 날씨 | F5: 외부온도 | G5: 내부온도 | H5: 외부습도 | I5: 내부습도
E6: 맑음 | F6: 13 | G6: 26 | H6: 0.28 | I6: 0.24
A9: 1. 금일 매출 실적 | B9: 실적 | C9: POS 매출 | E9: POS 외 매출 | G9: 총 매출 | I9: 객단가
C10: 매출액(원) | D10: 매출건수(건) | E10: 매출액(원) | F10: 매출건수(건) | G10: 총 매출액(원) | H10: 총 매출건수(건)
C11: 1742000 | D11: 139 | E11: =SUM(E55:I56) -> 315100 | F11: =SUM(E53:I54) -> 19 | G11: =C11+E11 -> 2057100 | H11: =D11+F11 -> 158 | I11: =G11/H11 -> 13019.62
A12: 2. 제품 판매량 | B12: 제품명 | C12: 생산량(ea) | D12: 손실량(ea) | E12: 시식량(ea) | F12: 기타(ea) In (+) / Out (-) | H12: 재고량(ea) | I12: 판매량(ea)
B13: 바게트 | C13: 53 | H13: 3 | I13: =C13-D13-D14*1/2-E13-E14*1/2+F13-H13-H14*1/2-I14*1/2 -> 50
B14: 바게트(H)
B15: 화바게트 | C15: 22 | H15: 8 | I15: =C15-D15-D16*1/2-E15-E16*1/2+F15-H15-H16*1/2-I16*1/2 -> 14
B16: 화바게트(H)
B17: 깜파뉴 | C17: 64 | I17: =C17-D17-D18*1/2-E17-E18*1/2+F17-H17-H18*1/2-I18*1/2 -> 64
B18: 깜파뉴(H)
B19: 식 빵 | C19: 16 | I19: =C19-D19-D20*1/2-E19-E20*1/2+F19-H19-H20*1/2-I20*1/2 -> 15.5
B20: 식 빵(H) | D20: 1
B21: 블랙올리브 | C21: 112 | D21: 1 | E21: 2 | I21: =C21-D21-E21+F21-H21 -> 109
B22: 허 브 | C22: 46 | D22: 1 | E22: 1 | H22: 7 | I22: =C22-D22-E22+F22-H22 -> 37
B23: 치아바타 | C23: 189 | D23: 2 | E23: 3 | H23: 13 | I23: =C23-D23-D24-E23-E24+F23+F24-H23-H24-I24 -> 169
B24: 화치아바타 | E24: 2
B25: 크로아상 | C25: 36 | D25: 4 | I25: =C25-D25-E25+F25-H25 -> 32
B26: 뺑오쇼콜라 | C26: 33 | I26: =C26-D26-E26+F26-H26 -> 33
B27: 플레인 스콘 | C27: 29 | I27: =C27-D27-E27+F27-H27 -> 29
B28: 크랜베리 스콘 | C28: 43 | I28: =C28-D28-E28+F28-H28 -> 43
B29: 브 레 첼 | C29: 10 | I29: =C29-D29-E29+F29-H29 -> 10
B30: 스틱브레첼 | C30: 105 | D30: 4 | I30: =C30-D30-D31-E30-E31+F30+F31-H30-H31-I31 -> 101
B31: 버터브레첼
B32: 호라산 통밀
B33: 호밀비트
B34: 호밀후르츠
B35: 구름빵
B36: 무화과 호밀스틱 | C36: 21 | I36: =C36-D36-E36+F36-H36 -> 21
B37: 봄날깜빠뉴 | I37: =C37-D37-D38*1/2-E37-E38*1/2+F37-H37-H38*1/2-I38*1/2 -> 0
B38: 봄날깜빠뉴(H)
B39: 여름메밀빵 | I39: =C39-D39-D40*1/2-E39-E40*1/2+F39-H39-H40*1/2-I40*1/2 -> 0
B40: 여름메밀빵(H)
B41: 가을애깜빠뉴 | I41: =C41-D41-D42*1/2-E41-E42*1/2+F41-H41-H42*1/2-I42*1/2 -> 0
B42: 가을애깜빠뉴(H)
B43: 슈톨렌
...

Sheet 26일
A1: 일 일 업 무 보 고 서
A2: 일 시 | C2: 2025 년 2 월 26 일 ( 목요일) | E2: 확인 | F2: 작성자 | H2: 누계 매출액
A3: 지 점 명 | C3: 여의도 | D3: 점 | F3: 유준모 | H3: =G11+'25일'!H3:I3 -> 49636200
E5: 날씨 | F5: 외부온도 | G5: 내부온도 | H5: 외부습도 | I5: 내부습도
E6: 흐림 | F6: 12 | G6: 26 | H6: 0.36 | I6: 0.25
A9: 1. 금일 매출 실적 | B9: 실적 | C9: POS 매출 | E9: POS 외 매출 | G9: 총 매출 | I9: 객단가
C10: 매출액(원) | D10: 매출건수(건) | E10: 매출액(원) | F10: 매출건수(건) | G10: 총 매출액(원) | H10: 총 매출건수(건)
C11: 1640300 | D11: 132 | E11: =SUM(E55:I56) -> 649100 | F11: =SUM(E53:I54) -> 11 | G11: =C11+E11 -> 2289400 | H11: =D11+F11 -> 143 | I11: =G11/H11 -> 16009.79
A12: 2. 제품 판매량 | B12: 제품명 | C12: 생산량(ea) | D12: 손실량(ea) | E12: 시식량(ea) | F12: 기타(ea) In (+) / Out (-) | H12: 재고량(ea) | I12: 판매량(ea)
B13: 바게트 | C13: 27 | H13: 5 | I13: =C13-D13-D14*1/2-E13-E14*1/2+F13-H13-H14*1/2-I14*1/2 -> 20
B14: 바게트(H) | D14: 1 | E14: 3
B15: 화바게트 | C15: 25 | H15: 6 | I15: =C15-D15-D16*1/2-E15-E16*1/2+F15-H15-H16*1/2-I16*1/2 -> 18
B16: 화바게트(H) | E16: 1 | H16: 1
B17: 깜파뉴 | C17: 24 | I17: =C17-D17-D18*1/2-E17-E18*1/2+F17-H17-H18*1/2-I18*1/2 -> 23.5
B18: 깜파뉴(H) | H18: 1
B19: 식 빵 | C19: 16 | I19: =C19-D19-D20*1/2-E19-E20*1/2+F19-H19-H20*1/2-I20*1/2 -> 16
B20: 식 빵(H)
B21: 블랙올리브 | C21: 109 | E21: 1 | H21: 24 | I21: =C21-D21-E21+F21-H21 -> 84
B22: 허 브 | C22: 55 | H22: 12 | I22: =C22-D22-E22+F22-H22 -> 43
B23: 치아바타 | C23: 180 | E23: 3 | H23: 3 | I23: =C23-D23-D24-E23-E24+F23+F24-H23-H24-I24 -> 169
B24: 화치아바타 | E24: 3 | H24: 2
B25: 크로아상 | C25: 36 | D25: 1 | E25: 1 | I25: =C25-D25-E25+F25-H25 -> 34
B26: 뺑오쇼콜라 | C26: 33 | I26: =C26-D26-E26+F26-H26 -> 33
B27: 플레인 스콘 | C27: 30 | D27: 1 | I27: =C27-D27-E27+F27-H27 -> 29
B28: 크랜베리 스콘 | C28: 39 | D28: 1 | E28: 1 | I28: =C28-D28-E28+F28-H28 -> 37
B29: 브 레 첼 | C29: 10 | I29: =C29-D29-E29+F29-H29 -> 10
B30: 스틱브레첼 | C30: 103 | I30: =C30-D30-D31-E30-E31+F30+F31-H30-H31-I31 -> 103
B31: 버터브레첼
B32: 호라산 통밀
B33: 호밀비트
B34: 호밀후르츠 | I34: 5
B35: 구름빵 | I35: 24
B36: 무화과 호밀스틱 | C36: 20 | I36: =C36-D36-E36+F36-H36 -> 20
B37: 봄날깜빠뉴 | I37: =C37-D37-D38*1/2-E37-E38*1/2+F37-H37-H38*1/2-I38*1/2 -> 0
B38: 봄날깜빠뉴(H)
B39: 여름메밀빵 | I39: =C39-D39-D40*1/2-E39-E40*1/2+F39-H39-H40*1/2-I40*1/2 -> 0
B40: 여름메밀빵(H)
B41: 가을애깜빠뉴 | I41: =C41-D41-D42*1/2-E41-E42*1/2+F41-H41-H42*1/2-I42*1/2 -> 0
B42: 가을애깜빠뉴(H)
B43: 슈톨렌
...

Sheet 27일
A1: 일 일 업 무 보 고 서
A2: 일 시 | C2: 2026 년 2월 27일 ( 금요일) | E2: 확인 | F2: 작성자 | H2: 누계 매출액
A3: 지 점 명 | C3: 여의도 | D3: 점 | F3: 정희주 | H3: =G11+'26일'!H3:I3 -> 51960700
E5: 날씨 | F5: 외부온도 | G5: 내부온도 | H5: 외부습도 | I5: 내부습도
E6: 맑음 | F6: 12 | G6: 26.5 | H6: 0.45 | I6: 0.24
A9: 1. 금일 매출 실적 | B9: 실적 | C9: POS 매출 | E9: POS 외 매출 | G9: 총 매출 | I9: 객단가
C10: 매출액(원) | D10: 매출건수(건) | E10: 매출액(원) | F10: 매출건수(건) | G10: 총 매출액(원) | H10: 총 매출건수(건)
C11: 2050200 | D11: 161 | E11: =SUM(E55:I56) -> 274300 | F11: =SUM(E53:I54) -> 14 | G11: =C11+E11 -> 2324500 | H11: =D11+F11 -> 175 | I11: =G11/H11 -> 13282.857
A12: 2. 제품 판매량 | B12: 제품명 | C12: 생산량(ea) | D12: 손실량(ea) | E12: 시식량(ea) | F12: 기타(ea) In (+) / Out (-) | H12: 재고량(ea) | I12: 판매량(ea)
B13: 바게트 | C13: 26 | I13: =C13-D13-D14*1/2-E13-E14*1/2+F13-H13-H14*1/2-I14*1/2 -> 26
B14: 바게트(H)
B15: 화바게트 | C15: 23 | I15: =C15-D15-D16*1/2-E15-E16*1/2+F15-H15-H16*1/2-I16*1/2 -> 23
B16: 화바게트(H)
B17: 깜파뉴 | C17: 16 | D17: 1 | I17: =C17-D17-D18*1/2-E17-E18*1/2+F17-H17-H18*1/2-I18*1/2 -> 15
B18: 깜파뉴(H)
B19: 식 빵 | C19: 16 | I19: =C19-D19-D20*1/2-E19-E20*1/2+F19-H19-H20*1/2-I20*1/2 -> 16
B20: 식 빵(H)
B21: 블랙올리브 | C21: 82 | E21: 3 | I21: =C21-D21-E21+F21-H21 -> 79
B22: 허 브 | C22: 42 | E22: 1 | I22: =C22-D22-E22+F22-H22 -> 41
B23: 치아바타 | C23: 147 | E23: 4 | I23: =C23-D23-D24-E23-E24+F23+F24-H23-H24-I24 -> 143
B24: 화치아바타
B25: 크로아상 | C25: 34 | D25: 3 | I25: =C25-D25-E25+F25-H25 -> 31
B26: 뺑오쇼콜라 | C26: 32 | I26: =C26-D26-E26+F26-H26 -> 32
B27: 플레인 스콘 | C27: 32 | I27: =C27-D27-E27+F27-H27 -> 32
B28: 크랜베리 스콘 | C28: 46 | D28: 5 | E28: 2 | I28: =C28-D28-E28+F28-H28 -> 39
B29: 브 레 첼 | C29: 10 | I29: =C29-D29-E29+F29-H29 -> 10
B30: 스틱브레첼 | C30: 106 | I30: =C30-D30-D31-E30-E31+F30+F31-H30-H31-I31 -> 106
B31: 버터브레첼
B32: 호라산 통밀
B33: 호밀비트
B34: 호밀후르츠
B35: 구름빵 | I35: 3
B36: 무화과 호밀스틱 | C36: 20 | I36: =C36-D36-E36+F36-H36 -> 20
B37: 봄날깜빠뉴 | I37: =C37-D37-D38*1/2-E37-E38*1/2+F37-H37-H38*1/2-I38*1/2 -> 0
B38: 봄날깜빠뉴(H)
B39: 여름메밀빵 | I39: =C39-D39-D40*1/2-E39-E40*1/2+F39-H39-H40*1/2-I40*1/2 -> 0
B40: 여름메밀빵(H)
B41: 가을애깜빠뉴 | I41: =C41-D41-D42*1/2-E41-E42*1/2+F41-H41-H42*1/2-I42*1/2 -> 0
B42: 가을애깜빠뉴(H)
B43: 슈톨렌
...

Sheet 28일
A1: 일 일 업 무 보 고 서
A2: 일 시 | C2: 2026년 2월 28일 (토요일) | E2: 확인 | F2: 작성자 | H2: 누계 매출액
A3: 지 점 명 | C3: 여의도 | D3: 점 | F3: 김윤희 | H3: =G11+'27일'!H3:I3 -> 54353900
E5: 날씨 | F5: 외부온도 | G5: 내부온도 | H5: 외부습도 | I5: 내부습도
E6: 맑음 | F6: 13 | G6: 26 | H6: 0.35 | I6: 0.25
A9: 1. 금일 매출 실적 | B9: 실적 | C9: POS 매출 | E9: POS 외 매출 | G9: 총 매출 | I9: 객단가
C10: 매출액(원) | D10: 매출건수(건) | E10: 매출액(원) | F10: 매출건수(건) | G10: 총 매출액(원) | H10: 총 매출건수(건)
